Workbook

Sheet Instructions
B2: Instructions
B3: Information on how to get started using this template.
B6: How to use this template
A8: 1. | B8: Start on the "Transactions" sheet by removing the sample transactions and enter your business transactions . After you have entered your transactions, place the transaction in the appropriate category.
A10: 2. | B10: The "Dashboard" and "Profit & Loss" sheets will automatically update based on the transactions.
A12: 3. | B12: If you want to change any of the categories, you can change them on the "Categories" sheet.
A14: 4. | B14: If you want to add new categories on the "Categories" sheet, first add a new row below the last one in that category type, type in the category name and select the category type from the drop down menu. Then go to the "Profit and Loss" sheet, select the row that shows #REF! and insert a new row below it. All the categories, including the new one will now show up. Your new category will now also be visible on the "Transactions" sheet.
A16: 5. | B16: To create a balance sheet, enter values in the shaded boxes on the "Balance Sheet".
B18: =HYPERLINK("https://www.xero.com/financial-statements/?xtid=x30googlesheets&utm_source=google&utm_medium=web&utm_campaign=googlesheets","Click here for more information about Xero and financial statements") -> Click here for more information about Xero and financial statements
B19: =HYPERLINK("https://www.youtube.com/watch?v=pKMs2emIMIw/?xtid=x30googlesheets&utm_source=google&utm_medium=web&utm_campaign=googlesheets","Click here for a quick video about this template") -> Click here for a quick video about this template

Sheet Transactions
B2: Transactions
B3: Enter transactions below. Transactions that you spent money on and Cost of Goods Sold should be a negative amount. Any money received should be a positive amount. After you have entered the Date, Description and Amount, select the appropriate category for the transaction.
B6: Category | C6: Date | D6: Description | E6: Amount
B7: Sales | C7: 43468 | D7: Consulting fees earned for project | E7: 800
B8: Travel | C8: 43491 | D8: Hotel reservation for trip in April | E8: -250
B9: Sales | C9: 43499 | D9: Fees earned for design project | E9: 1100
B10: Repairs | C10: 43501 | D10: Printer repair costs | E10: -150
B11: Sales | C11: 43536 | D11: Progress fees earned for project | E11: 1200

Sheet Dashboard
B2: Dashboard
B3: Automatically updated based on data in the "Transactions" sheet.
B5: Sales YTD | D5: ='Profit & Loss'!S10 -> 3100
B6: Total Profit (Loss) YTD | D6: ='Profit & Loss'!$S$41 -> 2700
B8: Data used for chart. Do not edit.
B9: =IFERROR(__xludf.DUMMYFUNCTION("QUERY(B26:D38,""select B,C,D where C<>0 OR D<>0"")"),"Month") -> Month | C9: =IFERROR(__xludf.DUMMYFUNCTION("""COMPUTED_VALUE"""),"Sales ") -> Sales | D9: =IFERROR(__xludf.DUMMYFUNCTION("""COMPUTED_VALUE"""),"Profit (Loss)") -> Profit (Loss)
B10: =IFERROR(__xludf.DUMMYFUNCTION("""COMPUTED_VALUE"""),2.0) -> 2 | C10: =IFERROR(__xludf.DUMMYFUNCTION("""COMPUTED_VALUE"""),800.0) -> 800 | D10: =IFERROR(__xludf.DUMMYFUNCTION("""COMPUTED_VALUE"""),550.0) -> 550
B11: =IFERROR(__xludf.DUMMYFUNCTION("""COMPUTED_VALUE"""),33.0) -> 33 | C11: =IFERROR(__xludf.DUMMYFUNCTION("""COMPUTED_VALUE"""),1100.0) -> 1100 | D11: =IFERROR(__xludf.DUMMYFUNCTION("""COMPUTED_VALUE"""),950.0) -> 950
B12: =IFERROR(__xludf.DUMMYFUNCTION("""COMPUTED_VALUE"""),61.0) -> 61 | C12: =IFERROR(__xludf.DUMMYFUNCTION("""COMPUTED_VALUE"""),1200.0) -> 1200 | D12: =IFERROR(__xludf.DUMMYFUNCTION("""COMPUTED_VALUE"""),1200.0) -> 1200
B26: Month | C26: Sales | D26: Profit (Loss)
B27: ='Profit & Loss'!G4 -> 2 | C27: ='Profit & Loss'!$G$10 -> 800 | D27: ='Profit & Loss'!$G$41 -> 550
B28: ='Profit & Loss'!H4 -> 33 | C28: ='Profit & Loss'!$H$10 -> 1100 | D28: ='Profit & Loss'!$H$41 -> 950
B29: ='Profit & Loss'!I4 -> 61 | C29: ='Profit & Loss'!$I$10 -> 1200 | D29: ='Profit & Loss'!$I$41 -> 1200
B30: ='Profit & Loss'!J4 -> 92 | C30: ='Profit & Loss'!$J$10 -> 0 | D30: ='Profit & Loss'!$J$41 -> 0
B31: ='Profit & Loss'!K4 -> 122 | C31: ='Profit & Loss'!$K$10 -> 0 | D31: ='Profit & Loss'!$K$41 -> 0
B32: ='Profit & Loss'!L4 -> 153 | C32: ='Profit & Loss'!$L$10 -> 0 | D32: ='Profit & Loss'!$L$41 -> 0
B33: ='Profit & Loss'!M4 -> 183 | C33: ='Profit & Loss'!$M$10 -> 0 | D33: ='Profit & Loss'!$M$41 -> 0
B34: ='Profit & Loss'!N4 -> 214 | C34: ='Profit & Loss'!$N$10 -> 0 | D34: ='Profit & Loss'!$N$41 -> 0
B35: ='Profit & Loss'!O4 -> 245 | C35: ='Profit & Loss'!$O$10 -> 0 | D35: ='Profit & Loss'!$O$41 -> 0
B36: ='Profit & Loss'!P4 -> 275 | C36: ='Profit & Loss'!$P$10 -> 0 | D36: ='Profit & Loss'!$P$41 -> 0
B37: ='Profit & Loss'!Q4 -> 306 | C37: ='Profit & Loss'!$Q$10 -> 0 | D37: ='Profit & Loss'!$Q$41 -> 0
B38: ='Profit & Loss'!R4 -> 336 | C38: ='Profit & Loss'!$R$10 -> 0 | D38: ='Profit & Loss'!$R$41 -> 0
B40: 3 Highest Sales Months
B41: =IFERROR(__xludf.DUMMYFUNCTION("if (ISError(query(B27:D38,""select B,C where (C<>0) order by C desc limit 3"",-1)), """", query(B27:D38,""select B,C where (C<>0) order by C desc limit 3"",-1))"),61.0) -> 61 | C41: =IFERROR(__xludf.DUMMYFUNCTION("""COMPUTED_VALUE"""),1200.0) -> 1200
B42: =IFERROR(__xludf.DUMMYFUNCTION("""COMPUTED_VALUE"""),33.0) -> 33 | C42: =IFERROR(__xludf.DUMMYFUNCTION("""COMPUTED_VALUE"""),1100.0) -> 1100
B43: =IFERROR(__xludf.DUMMYFUNCTION("""COMPUTED_VALUE"""),2.0) -> 2 | C43: =IFERROR(__xludf.DUMMYFUNCTION("""COMPUTED_VALUE"""),800.0) -> 800
B45: 3 Lowest Sales Months
B46: =IFERROR(__xludf.DUMMYFUNCTION("if (ISError(query(B27:D38,""select B,C where (C<>0) order by C asc limit 3"",-1)), """", query(B27:D38,""select B,C where (C<>0) order by C asc limit 3"",-1))"),2.0) -> 2 | C46: =IFERROR(__xludf.DUMMYFUNCTION("""COMPUTED_VALUE"""),800.0) -> 800
B47: =IFERROR(__xludf.DUMMYFUNCTION("""COMPUTED_VALUE"""),33.0) -> 33 | C47: =IFERROR(__xludf.DUMMYFUNCTION("""COMPUTED_VALUE"""),1100.0) -> 1100
B48: =IFERROR(__xludf.DUMMYFUNCTION("""COMPUTED_VALUE"""),61.0) -> 61 | C48: =IFERROR(__xludf.DUMMYFUNCTION("""COMPUTED_VALUE"""),1200.0) -> 1200
C49: -
B50: 3 Most Profitable Months
B51: =IFERROR(__xludf.DUMMYFUNCTION("if (ISError(query(B$27:D$38,""select B,D where (C<>0) order by D desc limit 3"",-1)), """", query(B$27:D$38,""select B,D where (C<>0) order by D desc limit 3"",-1))"),61.0) -> 61 | C51: =IFERROR(__xludf.DUMMYFUNCTION("""COMPUTED_VALUE"""),1200.0) -> 1200
B52: =IFERROR(__xludf.DUMMYFUNCTION("""COMPUTED_VALUE"""),33.0) -> 33 | C52: =IFERROR(__xludf.DUMMYFUNCTION("""COMPUTED_VALUE"""),950.0) -> 950
B53: =IFERROR(__xludf.DUMMYFUNCTION("""COMPUTED_VALUE"""),2.0) -> 2 | C53: =IFERROR(__xludf.DUMMYFUNCTION("""COMPUTED_VALUE"""),550.0) -> 550
B55: 3 Least Profitable Months
B56: =IFERROR(__xludf.DUMMYFUNCTION("if (ISError(query(B$27:D$38,""select B,D where (C<>0 or D<>0) order by D asc limit 3"",-1)), """", query(B$27:D$38,""select B,D where (C<>0 or D<>0) order by D asc limit 3"",-1))"),2.0) -> 2 | C56: =IFERROR(__xludf.DUMMYFUNCTION("""COMPUTED_VALUE"""),550.0) -> 550
B57: =IFERROR(__xludf.DUMMYFUNCTION("""COMPUTED_VALUE"""),33.0) -> 33 | C57: =IFERROR(__xludf.DUMMYFUNCTION("""COMPUTED_VALUE"""),950.0) -> 950
B58: =IFERROR(__xludf.DUMMYFUNCTION("""COMPUTED_VALUE"""),61.0) -> 61 | C58: =IFERROR(__xludf.DUMMYFUNCTION("""COMPUTED_VALUE"""),1200.0) -> 1200
B60: Data used for chart. Do not edit.
...

Sheet Profit & Loss
B2: Profit & Loss | G2: This sheet automatically summarizes revenues, costs, and expenses for the provided year based on the transactions listed in the "Transactions" sheet. Optionally, specify a growth rate percentage to create a projected Profit & Loss statement. Select cell F4 to choose the first month of your financial year. The rest of the dates will update.
C4: 20YY | F4: January | G4: =iferror(ifs(F4="January",date(0,1,1),F4="February",date(0,2,1),F4="March",date(0,3,1),F4="April",date(0,4,1),F4="May",date(0,5,1),F4="June",date(0,6,1),F4="July",date(0,7,1),F4="August",date(0,8,1),F4="September",date(0,9,1),F4="October",date(0,10,1),F4="November",date(0,11,1),F4="December",date(0,12,1)),Date(0,3,1)) -> 2 | H4: =date(0,MONTH(G$4)+1,1) -> 33 | I4: =date(0,MONTH(H$4)+1,1) -> 61 | J4: =date(0,MONTH(I$4)+1,1) -> 92 | K4: =date(0,MONTH(J$4)+1,1) -> 122 | L4: =date(0,MONTH(K$4)+1,1) -> 153 | M4: =date(0,MONTH(L$4)+1,1) -> 183 | N4: =date(0,MONTH(M$4)+1,1) -> 214 | O4: =date(0,MONTH(N$4)+1,1) -> 245 | ... R4: =date(0,MONTH(Q$4)+1,1) -> 336 | S4: Total YTD | T4: Growth Rate | U4: Projected
C5: Income
E6: Revenue
F7: =IFERROR(__xludf.DUMMYFUNCTION("FILTER(Categories!B:B,Categories!C:C=""Revenue"")"),"Sales ") -> Sales | G7: {=if(isblank($F7),,SUMIFS(Transactions!$E:$E,Transactions!$B:$B,$F7, MONTH(Transactions!$C:$C),MONTH(G$4)))} -> 800 | H7: {=if(isblank($F7),,SUMIFS(Transactions!$E:$E,Transactions!$B:$B,$F7, MONTH(Transactions!$C:$C),MONTH(H$4)))} -> 1100 | I7: {=if(isblank($F7),,SUMIFS(Transactions!$E:$E,Transactions!$B:$B,$F7, MONTH(Transactions!$C:$C),MONTH(I$4)))} -> 1200 | J7: {=if(isblank($F7),,SUMIFS(Transactions!$E:$E,Transactions!$B:$B,$F7, MONTH(Transactions!$C:$C),MONTH(J$4)))} -> 0 | K7: {=if(isblank($F7),,SUMIFS(Transactions!$E:$E,Transactions!$B:$B,$F7, MONTH(Transactions!$C:$C),MONTH(K$4)))} -> 0 | L7: {=if(isblank($F7),,SUMIFS(Transactions!$E:$E,Transactions!$B:$B,$F7, MONTH(Transactions!$C:$C),MONTH(L$4)))} -> 0 | M7: {=if(isblank($F7),,SUMIFS(Transactions!$E:$E,Transactions!$B:$B,$F7, MONTH(Transactions!$C:$C),MONTH(M$4)))} -> 0 | N7: {=if(isblank($F7),,SUMIFS(Transactions!$E:$E,Transactions!$B:$B,$F7, MONTH(Transactions!$C:$C),MONTH(N$4)))} -> 0 | ... R7: {=if(isblank($F7),,SUMIFS(Transactions!$E:$E,Transactions!$B:$B,$F7, MONTH(Transactions!$C:$C),MONTH(R$4)))} -> 0 | S7: =sum(G7:R7) -> 3100 | T7: 0.2 | U7: =S7*(1+T7) -> 3720
F8: =IFERROR(__xludf.DUMMYFUNCTION("""COMPUTED_VALUE"""),"Custom Sales 1") -> Custom Sales 1 | G8: {=if(isblank($F8),,SUMIFS(Transactions!$E:$E,Transactions!$B:$B,$F8, MONTH(Transactions!$C:$C),MONTH(G$4)))} -> 0 | H8: {=if(isblank($F8),,SUMIFS(Transactions!$E:$E,Transactions!$B:$B,$F8, MONTH(Transactions!$C:$C),MONTH(H$4)))} -> 0 | I8: {=if(isblank($F8),,SUMIFS(Transactions!$E:$E,Transactions!$B:$B,$F8, MONTH(Transactions!$C:$C),MONTH(I$4)))} -> 0 | J8: {=if(isblank($F8),,SUMIFS(Transactions!$E:$E,Transactions!$B:$B,$F8, MONTH(Transactions!$C:$C),MONTH(J$4)))} -> 0 | K8: {=if(isblank($F8),,SUMIFS(Transactions!$E:$E,Transactions!$B:$B,$F8, MONTH(Transactions!$C:$C),MONTH(K$4)))} -> 0 | L8: {=if(isblank($F8),,SUMIFS(Transactions!$E:$E,Transactions!$B:$B,$F8, MONTH(Transactions!$C:$C),MONTH(L$4)))} -> 0 | M8: {=if(isblank($F8),,SUMIFS(Transactions!$E:$E,Transactions!$B:$B,$F8, MONTH(Transactions!$C:$C),MONTH(M$4)))} -> 0 | N8: {=if(isblank($F8),,SUMIFS(Transactions!$E:$E,Transactions!$B:$B,$F8, MONTH(Transactions!$C:$C),MONTH(N$4)))} -> 0 | ... R8: {=if(isblank($F8),,SUMIFS(Transactions!$E:$E,Transactions!$B:$B,$F8, MONTH(Transactions!$C:$C),MONTH(R$4)))} -> 0 | S8: =sum(G8:R8) -> 0 | U8: =S8*(1+T8) -> 0
F9: =IFERROR(__xludf.DUMMYFUNCTION("""COMPUTED_VALUE"""),"Custom Sales 2") -> Custom Sales 2 | G9: {=if(isblank($F9),,SUMIFS(Transactions!$E:$E,Transactions!$B:$B,$F9, MONTH(Transactions!$C:$C),MONTH(G$4)))} -> 0 | H9: {=if(isblank($F9),,SUMIFS(Transactions!$E:$E,Transactions!$B:$B,$F9, MONTH(Transactions!$C:$C),MONTH(H$4)))} -> 0 | I9: {=if(isblank($F9),,SUMIFS(Transactions!$E:$E,Transactions!$B:$B,$F9, MONTH(Transactions!$C:$C),MONTH(I$4)))} -> 0 | J9: {=if(isblank($F9),,SUMIFS(Transactions!$E:$E,Transactions!$B:$B,$F9, MONTH(Transactions!$C:$C),MONTH(J$4)))} -> 0 | K9: {=if(isblank($F9),,SUMIFS(Transactions!$E:$E,Transactions!$B:$B,$F9, MONTH(Transactions!$C:$C),MONTH(K$4)))} -> 0 | L9: {=if(isblank($F9),,SUMIFS(Transactions!$E:$E,Transactions!$B:$B,$F9, MONTH(Transactions!$C:$C),MONTH(L$4)))} -> 0 | M9: {=if(isblank($F9),,SUMIFS(Transactions!$E:$E,Transactions!$B:$B,$F9, MONTH(Transactions!$C:$C),MONTH(M$4)))} -> 0 | N9: {=if(isblank($F9),,SUMIFS(Transactions!$E:$E,Transactions!$B:$B,$F9, MONTH(Transactions!$C:$C),MONTH(N$4)))} -> 0 | ... R9: {=if(isblank($F9),,SUMIFS(Transactions!$E:$E,Transactions!$B:$B,$F9, MONTH(Transactions!$C:$C),MONTH(R$4)))} -> 0 | S9: =sum(G9:R9) -> 0 | U9: =S9*(1+T9) -> 0
F10: Total sales | G10: =sum(G6:G9) -> 800 | H10: =sum(H6:H9) -> 1100 | I10: =sum(I6:I9) -> 1200 | J10: =sum(J6:J9) -> 0 | K10: =sum(K6:K9) -> 0 | L10: =sum(L6:L9) -> 0 | M10: =sum(M6:M9) -> 0 | N10: =sum(N6:N9) -> 0 | ... S10: =sum(S6:S9) -> 3100 | U10: =sum(U6:U9) -> 3720
E12: Cost of sales
F13: =IFERROR(__xludf.DUMMYFUNCTION("FILTER(Categories!B:B,Categories!C:C=""Cost of Goods Sold"")"),"Cost of Goods Sold") -> Cost of Goods Sold | G13: {=-if(isblank($F13),,SUMIFS(Transactions!$E:$E,Transactions!$B:$B,$F13, MONTH(Transactions!$C:$C),MONTH(G$4)))} -> 0 | H13: {=-if(isblank($F13),,SUMIFS(Transactions!$E:$E,Transactions!$B:$B,$F13, MONTH(Transactions!$C:$C),MONTH(H$4)))} -> 0 | I13: {=-if(isblank($F13),,SUMIFS(Transactions!$E:$E,Transactions!$B:$B,$F13, MONTH(Transactions!$C:$C),MONTH(I$4)))} -> 0 | J13: {=-if(isblank($F13),,SUMIFS(Transactions!$E:$E,Transactions!$B:$B,$F13, MONTH(Transactions!$C:$C),MONTH(J$4)))} -> 0 | K13: {=-if(isblank($F13),,SUMIFS(Transactions!$E:$E,Transactions!$B:$B,$F13, MONTH(Transactions!$C:$C),MONTH(K$4)))} -> 0 | L13: {=-if(isblank($F13),,SUMIFS(Transactions!$E:$E,Transactions!$B:$B,$F13, MONTH(Transactions!$C:$C),MONTH(L$4)))} -> 0 | M13: {=-if(isblank($F13),,SUMIFS(Transactions!$E:$E,Transactions!$B:$B,$F13, MONTH(Transactions!$C:$C),MONTH(M$4)))} -> 0 | N13: {=-if(isblank($F13),,SUMIFS(Transactions!$E:$E,Transactions!$B:$B,$F13, MONTH(Transactions!$C:$C),MONTH(N$4)))} -> 0 | ... R13: {=-if(isblank($F13),,SUMIFS(Transactions!$E:$E,Transactions!$B:$B,$F13, MONTH(Transactions!$C:$C),MONTH(R$4)))} -> 0 | S13: =sum(G13:R13) -> 0 | U13: =S13*(1+T13) -> 0
F14: =IFERROR(__xludf.DUMMYFUNCTION("""COMPUTED_VALUE"""),"Custom COGS 1") -> Custom COGS 1 | G14: {=-if(isblank($F14),,SUMIFS(Transactions!$E:$E,Transactions!$B:$B,$F14, MONTH(Transactions!$C:$C),MONTH(G$4)))} -> 0 | H14: {=-if(isblank($F14),,SUMIFS(Transactions!$E:$E,Transactions!$B:$B,$F14, MONTH(Transactions!$C:$C),MONTH(H$4)))} -> 0 | I14: {=-if(isblank($F14),,SUMIFS(Transactions!$E:$E,Transactions!$B:$B,$F14, MONTH(Transactions!$C:$C),MONTH(I$4)))} -> 0 | J14: {=-if(isblank($F14),,SUMIFS(Transactions!$E:$E,Transactions!$B:$B,$F14, MONTH(Transactions!$C:$C),MONTH(J$4)))} -> 0 | K14: {=-if(isblank($F14),,SUMIFS(Transactions!$E:$E,Transactions!$B:$B,$F14, MONTH(Transactions!$C:$C),MONTH(K$4)))} -> 0 | L14: {=-if(isblank($F14),,SUMIFS(Transactions!$E:$E,Transactions!$B:$B,$F14, MONTH(Transactions!$C:$C),MONTH(L$4)))} -> 0 | M14: {=-if(isblank($F14),,SUMIFS(Transactions!$E:$E,Transactions!$B:$B,$F14, MONTH(Transactions!$C:$C),MONTH(M$4)))} -> 0 | N14: {=-if(isblank($F14),,SUMIFS(Transactions!$E:$E,Transactions!$B:$B,$F14, MONTH(Transactions!$C:$C),MONTH(N$4)))} -> 0 | ... R14: {=-if(isblank($F14),,SUMIFS(Transactions!$E:$E,Transactions!$B:$B,$F14, MONTH(Transactions!$C:$C),MONTH(R$4)))} -> 0 | S14: =sum(G14:R14) -> 0 | U14: =S14*(1+T14) -> 0
F15: =IFERROR(__xludf.DUMMYFUNCTION("""COMPUTED_VALUE"""),"Custom COGS 2") -> Custom COGS 2 | G15: {=-if(isblank($F15),,SUMIFS(Transactions!$E:$E,Transactions!$B:$B,$F15, MONTH(Transactions!$C:$C),MONTH(G$4)))} -> 0 | H15: {=-if(isblank($F15),,SUMIFS(Transactions!$E:$E,Transactions!$B:$B,$F15, MONTH(Transactions!$C:$C),MONTH(H$4)))} -> 0 | I15: {=-if(isblank($F15),,SUMIFS(Transactions!$E:$E,Transactions!$B:$B,$F15, MONTH(Transactions!$C:$C),MONTH(I$4)))} -> 0 | J15: {=-if(isblank($F15),,SUMIFS(Transactions!$E:$E,Transactions!$B:$B,$F15, MONTH(Transactions!$C:$C),MONTH(J$4)))} -> 0 | K15: {=-if(isblank($F15),,SUMIFS(Transactions!$E:$E,Transactions!$B:$B,$F15, MONTH(Transactions!$C:$C),MONTH(K$4)))} -> 0 | L15: {=-if(isblank($F15),,SUMIFS(Transactions!$E:$E,Transactions!$B:$B,$F15, MONTH(Transactions!$C:$C),MONTH(L$4)))} -> 0 | M15: {=-if(isblank($F15),,SUMIFS(Transactions!$E:$E,Transactions!$B:$B,$F15, MONTH(Transactions!$C:$C),MONTH(M$4)))} -> 0 | N15: {=-if(isblank($F15),,SUMIFS(Transactions!$E:$E,Transactions!$B:$B,$F15, MONTH(Transactions!$C:$C),MONTH(N$4)))} -> 0 | ... R15: {=-if(isblank($F15),,SUMIFS(Transactions!$E:$E,Transactions!$B:$B,$F15, MONTH(Transactions!$C:$C),MONTH(R$4)))} -> 0 | S15: =sum(G15:R15) -> 0 | U15: =S15*(1+T15) -> 0
F16: Total cost of sales | G16: =sum(G12:G15) -> 0 | H16: =sum(H12:H15) -> 0 | I16: =sum(I12:I15) -> 0 | J16: =sum(J12:J15) -> 0 | K16: =sum(K12:K15) -> 0 | L16: =sum(L12:L15) -> 0 | M16: =sum(M12:M15) -> 0 | N16: =sum(N12:N15) -> 0 | ... S16: =sum(S12:S15) -> 0 | U16: =sum(U12:U15) -> 0
D18: Gross Margin | G18: =G10 - G16 -> 800 | H18: =H10 - H16 -> 1100 | I18: =I10 - I16 -> 1200 | J18: =J10 - J16 -> 0 | K18: =K10 - K16 -> 0 | L18: =L10 - L16 -> 0 | M18: =M10 - M16 -> 0 | N18: =N10 - N16 -> 0 | ... R18: =R10 - R16 -> 0 | S18: =sum(G18:R18) -> 3100 | U18: =U10-U16 -> 3720
C20: Expenses
F21: =IFERROR(__xludf.DUMMYFUNCTION("FILTER(Categories!B:B,Categories!C:C=""Expenses"")"),"Advertising") -> Advertising | G21: {=-if(isblank($F21),,SUMIFS(Transactions!$E:$E,Transactions!$B:$B,$F21, MONTH(Transactions!$C:$C),MONTH(G$4)))} -> 0 | H21: {=-if(isblank($F21),,SUMIFS(Transactions!$E:$E,Transactions!$B:$B,$F21, MONTH(Transactions!$C:$C),MONTH(H$4)))} -> 0 | I21: {=-if(isblank($F21),,SUMIFS(Transactions!$E:$E,Transactions!$B:$B,$F21, MONTH(Transactions!$C:$C),MONTH(I$4)))} -> 0 | J21: {=-if(isblank($F21),,SUMIFS(Transactions!$E:$E,Transactions!$B:$B,$F21, MONTH(Transactions!$C:$C),MONTH(J$4)))} -> 0 | K21: {=-if(isblank($F21),,SUMIFS(Transactions!$E:$E,Transactions!$B:$B,$F21, MONTH(Transactions!$C:$C),MONTH(K$4)))} -> 0 | L21: {=-if(isblank($F21),,SUMIFS(Transactions!$E:$E,Transactions!$B:$B,$F21, MONTH(Transactions!$C:$C),MONTH(L$4)))} -> 0 | M21: {=-if(isblank($F21),,SUMIFS(Transactions!$E:$E,Transactions!$B:$B,$F21, MONTH(Transactions!$C:$C),MONTH(M$4)))} -> 0 | N21: {=-if(isblank($F21),,SUMIFS(Transactions!$E:$E,Transactions!$B:$B,$F21, MONTH(Transactions!$C:$C),MONTH(N$4)))} -> 0 | ... R21: {=-if(isblank($F21),,SUMIFS(Transactions!$E:$E,Transactions!$B:$B,$F21, MONTH(Transactions!$C:$C),MONTH(R$4)))} -> 0 | S21: =sum(G21:R21) -> 0 | U21: =S21*(1+T21) -> 0
F22: =IFERROR(__xludf.DUMMYFUNCTION("""COMPUTED_VALUE"""),"Office Supplies") -> Office Supplies | G22: {=-if(isblank($F22),,SUMIFS(Transactions!$E:$E,Transactions!$B:$B,$F22, MONTH(Transactions!$C:$C),MONTH(G$4)))} -> 0 | H22: {=-if(isblank($F22),,SUMIFS(Transactions!$E:$E,Transactions!$B:$B,$F22, MONTH(Transactions!$C:$C),MONTH(H$4)))} -> 0 | I22: {=-if(isblank($F22),,SUMIFS(Transactions!$E:$E,Transactions!$B:$B,$F22, MONTH(Transactions!$C:$C),MONTH(I$4)))} -> 0 | J22: {=-if(isblank($F22),,SUMIFS(Transactions!$E:$E,Transactions!$B:$B,$F22, MONTH(Transactions!$C:$C),MONTH(J$4)))} -> 0 | K22: {=-if(isblank($F22),,SUMIFS(Transactions!$E:$E,Transactions!$B:$B,$F22, MONTH(Transactions!$C:$C),MONTH(K$4)))} -> 0 | L22: {=-if(isblank($F22),,SUMIFS(Transactions!$E:$E,Transactions!$B:$B,$F22, MONTH(Transactions!$C:$C),MONTH(L$4)))} -> 0 | M22: {=-if(isblank($F22),,SUMIFS(Transactions!$E:$E,Transactions!$B:$B,$F22, MONTH(Transactions!$C:$C),MONTH(M$4)))} -> 0 | N22: {=-if(isblank($F22),,SUMIFS(Transactions!$E:$E,Transactions!$B:$B,$F22, MONTH(Transactions!$C:$C),MONTH(N$4)))} -> 0 | ... R22: {=-if(isblank($F22),,SUMIFS(Transactions!$E:$E,Transactions!$B:$B,$F22, MONTH(Transactions!$C:$C),MONTH(R$4)))} -> 0 | S22: =sum(G22:R22) -> 0 | U22: =S22*(1+T22) -> 0
F23: =IFERROR(__xludf.DUMMYFUNCTION("""COMPUTED_VALUE"""),"Car/Truck") -> Car/Truck | G23: {=-if(isblank($F23),,SUMIFS(Transactions!$E:$E,Transactions!$B:$B,$F23, MONTH(Transactions!$C:$C),MONTH(G$4)))} -> 0 | H23: {=-if(isblank($F23),,SUMIFS(Transactions!$E:$E,Transactions!$B:$B,$F23, MONTH(Transactions!$C:$C),MONTH(H$4)))} -> 0 | I23: {=-if(isblank($F23),,SUMIFS(Transactions!$E:$E,Transactions!$B:$B,$F23, MONTH(Transactions!$C:$C),MONTH(I$4)))} -> 0 | J23: {=-if(isblank($F23),,SUMIFS(Transactions!$E:$E,Transactions!$B:$B,$F23, MONTH(Transactions!$C:$C),MONTH(J$4)))} -> 0 | K23: {=-if(isblank($F23),,SUMIFS(Transactions!$E:$E,Transactions!$B:$B,$F23, MONTH(Transactions!$C:$C),MONTH(K$4)))} -> 0 | L23: {=-if(isblank($F23),,SUMIFS(Transactions!$E:$E,Transactions!$B:$B,$F23, MONTH(Transactions!$C:$C),MONTH(L$4)))} -> 0 | M23: {=-if(isblank($F23),,SUMIFS(Transactions!$E:$E,Transactions!$B:$B,$F23, MONTH(Transactions!$C:$C),MONTH(M$4)))} -> 0 | N23: {=-if(isblank($F23),,SUMIFS(Transactions!$E:$E,Transactions!$B:$B,$F23, MONTH(Transactions!$C:$C),MONTH(N$4)))} -> 0 | ... R23: {=-if(isblank($F23),,SUMIFS(Transactions!$E:$E,Transactions!$B:$B,$F23, MONTH(Transactions!$C:$C),MONTH(R$4)))} -> 0 | S23: =sum(G23:R23) -> 0 | U23: =S23*(1+T23) -> 0
F24: =IFERROR(__xludf.DUMMYFUNCTION("""COMPUTED_VALUE"""),"Insurance") -> Insurance | G24: {=-if(isblank($F24),,SUMIFS(Transactions!$E:$E,Transactions!$B:$B,$F24, MONTH(Transactions!$C:$C),MONTH(G$4)))} -> 0 | H24: {=-if(isblank($F24),,SUMIFS(Transactions!$E:$E,Transactions!$B:$B,$F24, MONTH(Transactions!$C:$C),MONTH(H$4)))} -> 0 | I24: {=-if(isblank($F24),,SUMIFS(Transactions!$E:$E,Transactions!$B:$B,$F24, MONTH(Transactions!$C:$C),MONTH(I$4)))} -> 0 | J24: {=-if(isblank($F24),,SUMIFS(Transactions!$E:$E,Transactions!$B:$B,$F24, MONTH(Transactions!$C:$C),MONTH(J$4)))} -> 0 | K24: {=-if(isblank($F24),,SUMIFS(Transactions!$E:$E,Transactions!$B:$B,$F24, MONTH(Transactions!$C:$C),MONTH(K$4)))} -> 0 | L24: {=-if(isblank($F24),,SUMIFS(Transactions!$E:$E,Transactions!$B:$B,$F24, MONTH(Transactions!$C:$C),MONTH(L$4)))} -> 0 | M24: {=-if(isblank($F24),,SUMIFS(Transactions!$E:$E,Transactions!$B:$B,$F24, MONTH(Transactions!$C:$C),MONTH(M$4)))} -> 0 | N24: {=-if(isblank($F24),,SUMIFS(Transactions!$E:$E,Transactions!$B:$B,$F24, MONTH(Transactions!$C:$C),MONTH(N$4)))} -> 0 | ... R24: {=-if(isblank($F24),,SUMIFS(Transactions!$E:$E,Transactions!$B:$B,$F24, MONTH(Transactions!$C:$C),MONTH(R$4)))} -> 0 | S24: =sum(G24:R24) -> 0 | U24: =S24*(1+T24) -> 0
F25: =IFERROR(__xludf.DUMMYFUNCTION("""COMPUTED_VALUE"""),"Rent-Car/Equipment") -> Rent-Car/Equipment | G25: {=-if(isblank($F25),,SUMIFS(Transactions!$E:$E,Transactions!$B:$B,$F25, MONTH(Transactions!$C:$C),MONTH(G$4)))} -> 0 | H25: {=-if(isblank($F25),,SUMIFS(Transactions!$E:$E,Transactions!$B:$B,$F25, MONTH(Transactions!$C:$C),MONTH(H$4)))} -> 0 | I25: {=-if(isblank($F25),,SUMIFS(Transactions!$E:$E,Transactions!$B:$B,$F25, MONTH(Transactions!$C:$C),MONTH(I$4)))} -> 0 | J25: {=-if(isblank($F25),,SUMIFS(Transactions!$E:$E,Transactions!$B:$B,$F25, MONTH(Transactions!$C:$C),MONTH(J$4)))} -> 0 | K25: {=-if(isblank($F25),,SUMIFS(Transactions!$E:$E,Transactions!$B:$B,$F25, MONTH(Transactions!$C:$C),MONTH(K$4)))} -> 0 | L25: {=-if(isblank($F25),,SUMIFS(Transactions!$E:$E,Transactions!$B:$B,$F25, MONTH(Transactions!$C:$C),MONTH(L$4)))} -> 0 | M25: {=-if(isblank($F25),,SUMIFS(Transactions!$E:$E,Transactions!$B:$B,$F25, MONTH(Transactions!$C:$C),MONTH(M$4)))} -> 0 | N25: {=-if(isblank($F25),,SUMIFS(Transactions!$E:$E,Transactions!$B:$B,$F25, MONTH(Transactions!$C:$C),MONTH(N$4)))} -> 0 | ... R25: {=-if(isblank($F25),,SUMIFS(Transactions!$E:$E,Transactions!$B:$B,$F25, MONTH(Transactions!$C:$C),MONTH(R$4)))} -> 0 | S25: =sum(G25:R25) -> 0 | U25: =S25*(1+T25) -> 0
F26: =IFERROR(__xludf.DUMMYFUNCTION("""COMPUTED_VALUE"""),"Repairs") -> Repairs | G26: {=-if(isblank($F26),,SUMIFS(Transactions!$E:$E,Transactions!$B:$B,$F26, MONTH(Transactions!$C:$C),MONTH(G$4)))} -> 0 | H26: {=-if(isblank($F26),,SUMIFS(Transactions!$E:$E,Transactions!$B:$B,$F26, MONTH(Transactions!$C:$C),MONTH(H$4)))} -> 150 | I26: {=-if(isblank($F26),,SUMIFS(Transactions!$E:$E,Transactions!$B:$B,$F26, MONTH(Transactions!$C:$C),MONTH(I$4)))} -> 0 | J26: {=-if(isblank($F26),,SUMIFS(Transactions!$E:$E,Transactions!$B:$B,$F26, MONTH(Transactions!$C:$C),MONTH(J$4)))} -> 0 | K26: {=-if(isblank($F26),,SUMIFS(Transactions!$E:$E,Transactions!$B:$B,$F26, MONTH(Transactions!$C:$C),MONTH(K$4)))} -> 0 | L26: {=-if(isblank($F26),,SUMIFS(Transactions!$E:$E,Transactions!$B:$B,$F26, MONTH(Transactions!$C:$C),MONTH(L$4)))} -> 0 | M26: {=-if(isblank($F26),,SUMIFS(Transactions!$E:$E,Transactions!$B:$B,$F26, MONTH(Transactions!$C:$C),MONTH(M$4)))} -> 0 | N26: {=-if(isblank($F26),,SUMIFS(Transactions!$E:$E,Transactions!$B:$B,$F26, MONTH(Transactions!$C:$C),MONTH(N$4)))} -> 0 | ... R26: {=-if(isblank($F26),,SUMIFS(Transactions!$E:$E,Transactions!$B:$B,$F26, MONTH(Transactions!$C:$C),MONTH(R$4)))} -> 0 | S26: =sum(G26:R26) -> 150 | U26: =S26*(1+T26) -> 150
F27: =IFERROR(__xludf.DUMMYFUNCTION("""COMPUTED_VALUE"""),"Legal Expenses") -> Legal Expenses | G27: {=-if(isblank($F27),,SUMIFS(Transactions!$E:$E,Transactions!$B:$B,$F27, MONTH(Transactions!$C:$C),MONTH(G$4)))} -> 0 | H27: {=-if(isblank($F27),,SUMIFS(Transactions!$E:$E,Transactions!$B:$B,$F27, MONTH(Transactions!$C:$C),MONTH(H$4)))} -> 0 | I27: {=-if(isblank($F27),,SUMIFS(Transactions!$E:$E,Transactions!$B:$B,$F27, MONTH(Transactions!$C:$C),MONTH(I$4)))} -> 0 | J27: {=-if(isblank($F27),,SUMIFS(Transactions!$E:$E,Transactions!$B:$B,$F27, MONTH(Transactions!$C:$C),MONTH(J$4)))} -> 0 | K27: {=-if(isblank($F27),,SUMIFS(Transactions!$E:$E,Transactions!$B:$B,$F27, MONTH(Transactions!$C:$C),MONTH(K$4)))} -> 0 | L27: {=-if(isblank($F27),,SUMIFS(Transactions!$E:$E,Transactions!$B:$B,$F27, MONTH(Transactions!$C:$C),MONTH(L$4)))} -> 0 | M27: {=-if(isblank($F27),,SUMIFS(Transactions!$E:$E,Transactions!$B:$B,$F27, MONTH(Transactions!$C:$C),MONTH(M$4)))} -> 0 | N27: {=-if(isblank($F27),,SUMIFS(Transactions!$E:$E,Transactions!$B:$B,$F27, MONTH(Transactions!$C:$C),MONTH(N$4)))} -> 0 | ... R27: {=-if(isblank($F27),,SUMIFS(Transactions!$E:$E,Transactions!$B:$B,$F27, MONTH(Transactions!$C:$C),MONTH(R$4)))} -> 0 | S27: =sum(G27:R27) -> 0 | U27: =S27*(1+T27) -> 0
F28: =IFERROR(__xludf.DUMMYFUNCTION("""COMPUTED_VALUE"""),"Contractors") -> Contractors | G28: {=-if(isblank($F28),,SUMIFS(Transactions!$E:$E,Transactions!$B:$B,$F28, MONTH(Transactions!$C:$C),MONTH(G$4)))} -> 0 | H28: {=-if(isblank($F28),,SUMIFS(Transactions!$E:$E,Transactions!$B:$B,$F28, MONTH(Transactions!$C:$C),MONTH(H$4)))} -> 0 | I28: {=-if(isblank($F28),,SUMIFS(Transactions!$E:$E,Transactions!$B:$B,$F28, MONTH(Transactions!$C:$C),MONTH(I$4)))} -> 0 | J28: {=-if(isblank($F28),,SUMIFS(Transactions!$E:$E,Transactions!$B:$B,$F28, MONTH(Transactions!$C:$C),MONTH(J$4)))} -> 0 | K28: {=-if(isblank($F28),,SUMIFS(Transactions!$E:$E,Transactions!$B:$B,$F28, MONTH(Transactions!$C:$C),MONTH(K$4)))} -> 0 | L28: {=-if(isblank($F28),,SUMIFS(Transactions!$E:$E,Transactions!$B:$B,$F28, MONTH(Transactions!$C:$C),MONTH(L$4)))} -> 0 | M28: {=-if(isblank($F28),,SUMIFS(Transactions!$E:$E,Transactions!$B:$B,$F28, MONTH(Transactions!$C:$C),MONTH(M$4)))} -> 0 | N28: {=-if(isblank($F28),,SUMIFS(Transactions!$E:$E,Transactions!$B:$B,$F28, MONTH(Transactions!$C:$C),MONTH(N$4)))} -> 0 | ... R28: {=-if(isblank($F28),,SUMIFS(Transactions!$E:$E,Transactions!$B:$B,$F28, MONTH(Transactions!$C:$C),MONTH(R$4)))} -> 0 | S28: =sum(G28:R28) -> 0 | U28: =S28*(1+T28) -> 0
F29: =IFERROR(__xludf.DUMMYFUNCTION("""COMPUTED_VALUE"""),"Travel") -> Travel | G29: {=-if(isblank($F29),,SUMIFS(Transactions!$E:$E,Transactions!$B:$B,$F29, MONTH(Transactions!$C:$C),MONTH(G$4)))} -> 250 | H29: {=-if(isblank($F29),,SUMIFS(Transactions!$E:$E,Transactions!$B:$B,$F29, MONTH(Transactions!$C:$C),MONTH(H$4)))} -> 0 | I29: {=-if(isblank($F29),,SUMIFS(Transactions!$E:$E,Transactions!$B:$B,$F29, MONTH(Transactions!$C:$C),MONTH(I$4)))} -> 0 | J29: {=-if(isblank($F29),,SUMIFS(Transactions!$E:$E,Transactions!$B:$B,$F29, MONTH(Transactions!$C:$C),MONTH(J$4)))} -> 0 | K29: {=-if(isblank($F29),,SUMIFS(Transactions!$E:$E,Transactions!$B:$B,$F29, MONTH(Transactions!$C:$C),MONTH(K$4)))} -> 0 | L29: {=-if(isblank($F29),,SUMIFS(Transactions!$E:$E,Transactions!$B:$B,$F29, MONTH(Transactions!$C:$C),MONTH(L$4)))} -> 0 | M29: {=-if(isblank($F29),,SUMIFS(Transactions!$E:$E,Transactions!$B:$B,$F29, MONTH(Transactions!$C:$C),MONTH(M$4)))} -> 0 | N29: {=-if(isblank($F29),,SUMIFS(Transactions!$E:$E,Transactions!$B:$B,$F29, MONTH(Transactions!$C:$C),MONTH(N$4)))} -> 0 | ... R29: {=-if(isblank($F29),,SUMIFS(Transactions!$E:$E,Transactions!$B:$B,$F29, MONTH(Transactions!$C:$C),MONTH(R$4)))} -> 0 | S29: =sum(G29:R29) -> 250 | U29: =S29*(1+T29) -> 250
F30: =IFERROR(__xludf.DUMMYFUNCTION("""COMPUTED_VALUE"""),"Meals & Entertainment") -> Meals & Entertainment | G30: {=-if(isblank($F30),,SUMIFS(Transactions!$E:$E,Transactions!$B:$B,$F30, MONTH(Transactions!$C:$C),MONTH(G$4)))} -> 0 | H30: {=-if(isblank($F30),,SUMIFS(Transactions!$E:$E,Transactions!$B:$B,$F30, MONTH(Transactions!$C:$C),MONTH(H$4)))} -> 0 | I30: {=-if(isblank($F30),,SUMIFS(Transactions!$E:$E,Transactions!$B:$B,$F30, MONTH(Transactions!$C:$C),MONTH(I$4)))} -> 0 | J30: {=-if(isblank($F30),,SUMIFS(Transactions!$E:$E,Transactions!$B:$B,$F30, MONTH(Transactions!$C:$C),MONTH(J$4)))} -> 0 | K30: {=-if(isblank($F30),,SUMIFS(Transactions!$E:$E,Transactions!$B:$B,$F30, MONTH(Transactions!$C:$C),MONTH(K$4)))} -> 0 | L30: {=-if(isblank($F30),,SUMIFS(Transactions!$E:$E,Transactions!$B:$B,$F30, MONTH(Transactions!$C:$C),MONTH(L$4)))} -> 0 | M30: {=-if(isblank($F30),,SUMIFS(Transactions!$E:$E,Transactions!$B:$B,$F30, MONTH(Transactions!$C:$C),MONTH(M$4)))} -> 0 | N30: {=-if(isblank($F30),,SUMIFS(Transactions!$E:$E,Transactions!$B:$B,$F30, MONTH(Transactions!$C:$C),MONTH(N$4)))} -> 0 | ... R30: {=-if(isblank($F30),,SUMIFS(Transactions!$E:$E,Transactions!$B:$B,$F30, MONTH(Transactions!$C:$C),MONTH(R$4)))} -> 0 | S30: =sum(G30:R30) -> 0 | U30: =S30*(1+T30) -> 0
F31: =IFERROR(__xludf.DUMMYFUNCTION("""COMPUTED_VALUE"""),"Utilities") -> Utilities | G31: {=-if(isblank($F31),,SUMIFS(Transactions!$E:$E,Transactions!$B:$B,$F31, MONTH(Transactions!$C:$C),MONTH(G$4)))} -> 0 | H31: {=-if(isblank($F31),,SUMIFS(Transactions!$E:$E,Transactions!$B:$B,$F31, MONTH(Transactions!$C:$C),MONTH(H$4)))} -> 0 | I31: {=-if(isblank($F31),,SUMIFS(Transactions!$E:$E,Transactions!$B:$B,$F31, MONTH(Transactions!$C:$C),MONTH(I$4)))} -> 0 | J31: {=-if(isblank($F31),,SUMIFS(Transactions!$E:$E,Transactions!$B:$B,$F31, MONTH(Transactions!$C:$C),MONTH(J$4)))} -> 0 | K31: {=-if(isblank($F31),,SUMIFS(Transactions!$E:$E,Transactions!$B:$B,$F31, MONTH(Transactions!$C:$C),MONTH(K$4)))} -> 0 | L31: {=-if(isblank($F31),,SUMIFS(Transactions!$E:$E,Transactions!$B:$B,$F31, MONTH(Transactions!$C:$C),MONTH(L$4)))} -> 0 | M31: {=-if(isblank($F31),,SUMIFS(Transactions!$E:$E,Transactions!$B:$B,$F31, MONTH(Transactions!$C:$C),MONTH(M$4)))} -> 0 | N31: {=-if(isblank($F31),,SUMIFS(Transactions!$E:$E,Transactions!$B:$B,$F31, MONTH(Transactions!$C:$C),MONTH(N$4)))} -> 0 | ... R31: {=-if(isblank($F31),,SUMIFS(Transactions!$E:$E,Transactions!$B:$B,$F31, MONTH(Transactions!$C:$C),MONTH(R$4)))} -> 0 | S31: =sum(G31:R31) -> 0 | U31: =S31*(1+T31) -> 0
F32: =IFERROR(__xludf.DUMMYFUNCTION("""COMPUTED_VALUE"""),"Rent") -> Rent | G32: {=-if(isblank($F32),,SUMIFS(Transactions!$E:$E,Transactions!$B:$B,$F32, MONTH(Transactions!$C:$C),MONTH(G$4)))} -> 0 | H32: {=-if(isblank($F32),,SUMIFS(Transactions!$E:$E,Transactions!$B:$B,$F32, MONTH(Transactions!$C:$C),MONTH(H$4)))} -> 0 | I32: {=-if(isblank($F32),,SUMIFS(Transactions!$E:$E,Transactions!$B:$B,$F32, MONTH(Transactions!$C:$C),MONTH(I$4)))} -> 0 | J32: {=-if(isblank($F32),,SUMIFS(Transactions!$E:$E,Transactions!$B:$B,$F32, MONTH(Transactions!$C:$C),MONTH(J$4)))} -> 0 | K32: {=-if(isblank($F32),,SUMIFS(Transactions!$E:$E,Transactions!$B:$B,$F32, MONTH(Transactions!$C:$C),MONTH(K$4)))} -> 0 | L32: {=-if(isblank($F32),,SUMIFS(Transactions!$E:$E,Transactions!$B:$B,$F32, MONTH(Transactions!$C:$C),MONTH(L$4)))} -> 0 | M32: {=-if(isblank($F32),,SUMIFS(Transactions!$E:$E,Transactions!$B:$B,$F32, MONTH(Transactions!$C:$C),MONTH(M$4)))} -> 0 | N32: {=-if(isblank($F32),,SUMIFS(Transactions!$E:$E,Transactions!$B:$B,$F32, MONTH(Transactions!$C:$C),MONTH(N$4)))} -> 0 | ... R32: {=-if(isblank($F32),,SUMIFS(Transactions!$E:$E,Transactions!$B:$B,$F32, MONTH(Transactions!$C:$C),MONTH(R$4)))} -> 0 | S32: =sum(G32:R32) -> 0 | U32: =S32*(1+T32) -> 0
F33: =IFERROR(__xludf.DUMMYFUNCTION("""COMPUTED_VALUE"""),"Loan Expenses") -> Loan Expenses | G33: {=-if(isblank($F33),,SUMIFS(Transactions!$E:$E,Transactions!$B:$B,$F33, MONTH(Transactions!$C:$C),MONTH(G$4)))} -> 0 | H33: {=-if(isblank($F33),,SUMIFS(Transactions!$E:$E,Transactions!$B:$B,$F33, MONTH(Transactions!$C:$C),MONTH(H$4)))} -> 0 | I33: {=-if(isblank($F33),,SUMIFS(Transactions!$E:$E,Transactions!$B:$B,$F33, MONTH(Transactions!$C:$C),MONTH(I$4)))} -> 0 | J33: {=-if(isblank($F33),,SUMIFS(Transactions!$E:$E,Transactions!$B:$B,$F33, MONTH(Transactions!$C:$C),MONTH(J$4)))} -> 0 | K33: {=-if(isblank($F33),,SUMIFS(Transactions!$E:$E,Transactions!$B:$B,$F33, MONTH(Transactions!$C:$C),MONTH(K$4)))} -> 0 | L33: {=-if(isblank($F33),,SUMIFS(Transactions!$E:$E,Transactions!$B:$B,$F33, MONTH(Transactions!$C:$C),MONTH(L$4)))} -> 0 | M33: {=-if(isblank($F33),,SUMIFS(Transactions!$E:$E,Transactions!$B:$B,$F33, MONTH(Transactions!$C:$C),MONTH(M$4)))} -> 0 | N33: {=-if(isblank($F33),,SUMIFS(Transactions!$E:$E,Transactions!$B:$B,$F33, MONTH(Transactions!$C:$C),MONTH(N$4)))} -> 0 | ... R33: {=-if(isblank($F33),,SUMIFS(Transactions!$E:$E,Transactions!$B:$B,$F33, MONTH(Transactions!$C:$C),MONTH(R$4)))} -> 0 | S33: =sum(G33:R33) -> 0 | U33: =S33*(1+T33) -> 0
F34: =IFERROR(__xludf.DUMMYFUNCTION("""COMPUTED_VALUE"""),"Taxes and Licenses") -> Taxes and Licenses | G34: {=-if(isblank($F34),,SUMIFS(Transactions!$E:$E,Transactions!$B:$B,$F34, MONTH(Transactions!$C:$C),MONTH(G$4)))} -> 0 | H34: {=-if(isblank($F34),,SUMIFS(Transactions!$E:$E,Transactions!$B:$B,$F34, MONTH(Transactions!$C:$C),MONTH(H$4)))} -> 0 | I34: {=-if(isblank($F34),,SUMIFS(Transactions!$E:$E,Transactions!$B:$B,$F34, MONTH(Transactions!$C:$C),MONTH(I$4)))} -> 0 | J34: {=-if(isblank($F34),,SUMIFS(Transactions!$E:$E,Transactions!$B:$B,$F34, MONTH(Transactions!$C:$C),MONTH(J$4)))} -> 0 | K34: {=-if(isblank($F34),,SUMIFS(Transactions!$E:$E,Transactions!$B:$B,$F34, MONTH(Transactions!$C:$C),MONTH(K$4)))} -> 0 | L34: {=-if(isblank($F34),,SUMIFS(Transactions!$E:$E,Transactions!$B:$B,$F34, MONTH(Transactions!$C:$C),MONTH(L$4)))} -> 0 | M34: {=-if(isblank($F34),,SUMIFS(Transactions!$E:$E,Transactions!$B:$B,$F34, MONTH(Transactions!$C:$C),MONTH(M$4)))} -> 0 | N34: {=-if(isblank($F34),,SUMIFS(Transactions!$E:$E,Transactions!$B:$B,$F34, MONTH(Transactions!$C:$C),MONTH(N$4)))} -> 0 | ... R34: {=-if(isblank($F34),,SUMIFS(Transactions!$E:$E,Transactions!$B:$B,$F34, MONTH(Transactions!$C:$C),MONTH(R$4)))} -> 0 | S34: =sum(G34:R34) -> 0 | U34: =S34*(1+T34) -> 0
F35: =IFERROR(__xludf.DUMMYFUNCTION("""COMPUTED_VALUE"""),"Other Expenses") -> Other Expenses | G35: {=-if(isblank($F35),,SUMIFS(Transactions!$E:$E,Transactions!$B:$B,$F35, MONTH(Transactions!$C:$C),MONTH(G$4)))} -> 0 | H35: {=-if(isblank($F35),,SUMIFS(Transactions!$E:$E,Transactions!$B:$B,$F35, MONTH(Transactions!$C:$C),MONTH(H$4)))} -> 0 | I35: {=-if(isblank($F35),,SUMIFS(Transactions!$E:$E,Transactions!$B:$B,$F35, MONTH(Transactions!$C:$C),MONTH(I$4)))} -> 0 | J35: {=-if(isblank($F35),,SUMIFS(Transactions!$E:$E,Transactions!$B:$B,$F35, MONTH(Transactions!$C:$C),MONTH(J$4)))} -> 0 | K35: {=-if(isblank($F35),,SUMIFS(Transactions!$E:$E,Transactions!$B:$B,$F35, MONTH(Transactions!$C:$C),MONTH(K$4)))} -> 0 | L35: {=-if(isblank($F35),,SUMIFS(Transactions!$E:$E,Transactions!$B:$B,$F35, MONTH(Transactions!$C:$C),MONTH(L$4)))} -> 0 | M35: {=-if(isblank($F35),,SUMIFS(Transactions!$E:$E,Transactions!$B:$B,$F35, MONTH(Transactions!$C:$C),MONTH(M$4)))} -> 0 | N35: {=-if(isblank($F35),,SUMIFS(Transactions!$E:$E,Transactions!$B:$B,$F35, MONTH(Transactions!$C:$C),MONTH(N$4)))} -> 0 | ... R35: {=-if(isblank($F35),,SUMIFS(Transactions!$E:$E,Transactions!$B:$B,$F35, MONTH(Transactions!$C:$C),MONTH(R$4)))} -> 0 | S35: =sum(G35:R35) -> 0
F36: =IFERROR(__xludf.DUMMYFUNCTION("""COMPUTED_VALUE"""),"Custom Expense 1") -> Custom Expense 1 | G36: {=-if(isblank($F36),,SUMIFS(Transactions!$E:$E,Transactions!$B:$B,$F36, MONTH(Transactions!$C:$C),MONTH(G$4)))} -> 0 | H36: {=-if(isblank($F36),,SUMIFS(Transactions!$E:$E,Transactions!$B:$B,$F36, MONTH(Transactions!$C:$C),MONTH(H$4)))} -> 0 | I36: {=-if(isblank($F36),,SUMIFS(Transactions!$E:$E,Transactions!$B:$B,$F36, MONTH(Transactions!$C:$C),MONTH(I$4)))} -> 0 | J36: {=-if(isblank($F36),,SUMIFS(Transactions!$E:$E,Transactions!$B:$B,$F36, MONTH(Transactions!$C:$C),MONTH(J$4)))} -> 0 | K36: {=-if(isblank($F36),,SUMIFS(Transactions!$E:$E,Transactions!$B:$B,$F36, MONTH(Transactions!$C:$C),MONTH(K$4)))} -> 0 | L36: {=-if(isblank($F36),,SUMIFS(Transactions!$E:$E,Transactions!$B:$B,$F36, MONTH(Transactions!$C:$C),MONTH(L$4)))} -> 0 | M36: {=-if(isblank($F36),,SUMIFS(Transactions!$E:$E,Transactions!$B:$B,$F36, MONTH(Transactions!$C:$C),MONTH(M$4)))} -> 0 | N36: {=-if(isblank($F36),,SUMIFS(Transactions!$E:$E,Transactions!$B:$B,$F36, MONTH(Transactions!$C:$C),MONTH(N$4)))} -> 0 | ... R36: {=-if(isblank($F36),,SUMIFS(Transactions!$E:$E,Transactions!$B:$B,$F36, MONTH(Transactions!$C:$C),MONTH(R$4)))} -> 0 | S36: =sum(G36:R36) -> 0
F37: =IFERROR(__xludf.DUMMYFUNCTION("""COMPUTED_VALUE"""),"Custom Expense 2") -> Custom Expense 2 | G37: {=-if(isblank($F37),,SUMIFS(Transactions!$E:$E,Transactions!$B:$B,$F37, MONTH(Transactions!$C:$C),MONTH(G$4)))} -> 0 | H37: {=-if(isblank($F37),,SUMIFS(Transactions!$E:$E,Transactions!$B:$B,$F37, MONTH(Transactions!$C:$C),MONTH(H$4)))} -> 0 | I37: {=-if(isblank($F37),,SUMIFS(Transactions!$E:$E,Transactions!$B:$B,$F37, MONTH(Transactions!$C:$C),MONTH(I$4)))} -> 0 | J37: {=-if(isblank($F37),,SUMIFS(Transactions!$E:$E,Transactions!$B:$B,$F37, MONTH(Transactions!$C:$C),MONTH(J$4)))} -> 0 | K37: {=-if(isblank($F37),,SUMIFS(Transactions!$E:$E,Transactions!$B:$B,$F37, MONTH(Transactions!$C:$C),MONTH(K$4)))} -> 0 | L37: {=-if(isblank($F37),,SUMIFS(Transactions!$E:$E,Transactions!$B:$B,$F37, MONTH(Transactions!$C:$C),MONTH(L$4)))} -> 0 | M37: {=-if(isblank($F37),,SUMIFS(Transactions!$E:$E,Transactions!$B:$B,$F37, MONTH(Transactions!$C:$C),MONTH(M$4)))} -> 0 | N37: {=-if(isblank($F37),,SUMIFS(Transactions!$E:$E,Transactions!$B:$B,$F37, MONTH(Transactions!$C:$C),MONTH(N$4)))} -> 0 | ... R37: {=-if(isblank($F37),,SUMIFS(Transactions!$E:$E,Transactions!$B:$B,$F37, MONTH(Transactions!$C:$C),MONTH(R$4)))} -> 0 | S37: =sum(G37:R37) -> 0 | U37: =S37*(1+T37) -> 0
F38: =IFERROR(__xludf.DUMMYFUNCTION("""COMPUTED_VALUE"""),"Custom Expense 3") -> Custom Expense 3 | G38: {=-if(isblank($F38),,SUMIFS(Transactions!$E:$E,Transactions!$B:$B,$F38, MONTH(Transactions!$C:$C),MONTH(G$4)))} -> 0 | H38: {=-if(isblank($F38),,SUMIFS(Transactions!$E:$E,Transactions!$B:$B,$F38, MONTH(Transactions!$C:$C),MONTH(H$4)))} -> 0 | I38: {=-if(isblank($F38),,SUMIFS(Transactions!$E:$E,Transactions!$B:$B,$F38, MONTH(Transactions!$C:$C),MONTH(I$4)))} -> 0 | J38: {=-if(isblank($F38),,SUMIFS(Transactions!$E:$E,Transactions!$B:$B,$F38, MONTH(Transactions!$C:$C),MONTH(J$4)))} -> 0 | K38: {=-if(isblank($F38),,SUMIFS(Transactions!$E:$E,Transactions!$B:$B,$F38, MONTH(Transactions!$C:$C),MONTH(K$4)))} -> 0 | L38: {=-if(isblank($F38),,SUMIFS(Transactions!$E:$E,Transactions!$B:$B,$F38, MONTH(Transactions!$C:$C),MONTH(L$4)))} -> 0 | M38: {=-if(isblank($F38),,SUMIFS(Transactions!$E:$E,Transactions!$B:$B,$F38, MONTH(Transactions!$C:$C),MONTH(M$4)))} -> 0 | N38: {=-if(isblank($F38),,SUMIFS(Transactions!$E:$E,Transactions!$B:$B,$F38, MONTH(Transactions!$C:$C),MONTH(N$4)))} -> 0 | ... R38: {=-if(isblank($F38),,SUMIFS(Transactions!$E:$E,Transactions!$B:$B,$F38, MONTH(Transactions!$C:$C),MONTH(R$4)))} -> 0 | S38: =sum(G38:R38) -> 0 | U38: =S38*(1+T38) -> 0
F39: Total expenses | G39: =sum(G20:G38) -> 250 | H39: =sum(H20:H38) -> 150 | I39: =sum(I20:I38) -> 0 | J39: =sum(J20:J38) -> 0 | K39: =sum(K20:K38) -> 0 | L39: =sum(L20:L38) -> 0 | M39: =sum(M20:M38) -> 0 | N39: =sum(N20:N38) -> 0 | ... S39: =sum(S20:S38) -> 400 | U39: =sum(U20:U38) -> 400
F41: Total Profit (Loss) | G41: =G18-G39 -> 550 | H41: =H18-H39 -> 950 | I41: =I18-I39 -> 1200 | J41: =J18-J39 -> 0 | K41: =K18-K39 -> 0 | L41: =L18-L39 -> 0 | M41: =M18-M39 -> 0 | N41: =N18-N39 -> 0 | ... R41: =R18-R39 -> 0 | S41: =sum(G41:R41) -> 2700 | U41: =U18-U39 -> 3320

Sheet Categories
B2: Categories
B3: Use this sheet to define expense, cost, and revenue categories. These categories are used to populate other sheets in this spreadsheet.
B5: Category Name | C5: Category Type
B7: Advertising | C7: Expenses
B8: Office Supplies | C8: Expenses
B9: Car/Truck | C9: Expenses
B10: Insurance | C10: Expenses
B11: Rent-Car/Equipment | C11: Expenses
B12: Repairs | C12: Expenses
B13: Legal Expenses | C13: Expenses
B14: Contractors | C14: Expenses
B15: Travel | C15: Expenses
B16: Meals & Entertainment | C16: Expenses
B17: Utilities | C17: Expenses
... B30: Custom Sales 2 | C30: Revenue

Sheet Balance Sheet
F1: As of
B2: Balance Sheet | F2: DD/MM/YYYY
B3: This sheet lists assets and liabilities. Enter values in the shaded cells below.
B5: Assets
D7: Cash and Cash Equivalents
E8: Checking Accounts
E9: Saving Accounts
E10: Total Cash | F10: =sum(F7:F9) -> 0
D12: Current Assets
E13: Accounts Receivable (net)
E14: Inventory
E15: Prepayments
E16: Total Current Assets | F16: =sum(F12:F15) -> 0
D18: Property, Plant and Equipment
E19: Vehicles (net)
E20: Furniture & Fixtures (net)
E21: Equipment (net)
E22: Buildings (net)
E23: Land
E24: Total Property, Plant and Equipment | F24: =sum(F18:F23) -> 0
D26: Other Assets
E27: Other Assets
E28: Total Other Assets | F28: =sum(F26:F27) -> 0
C30: Total assets | F30: =sum(F10,F16,F24,F28) -> 0
B32: Liabilities and Owner's Equity
D34: Current Liabilities
E35: Accounts payable
E36: Notes payable
E37: Other Current Liabilities
E38: Total Current Liabilities | F38: =sum(F34:F37) -> 0
D40: Non-Current Liabilities
E41: Long-term Notes Payable
E42: Loans
E43: Other Non-Current Liabilities
E44: Total Non-Current Liabilities | F44: =sum(F40:F43) -> 0
D46: Total liabilities | F46: =sum(F38,F44) -> 0
D48: Owners' equity
E49: Capital Stock
E50: Retained Earnings
E51: Other
...
