Workbook

Sheet Budget
B1: Budget
H4: =IFERROR(__xludf.DUMMYFUNCTION("SPARKLINE(H11,{""charttype"",""column"";""ymin"", 0; ""ymax"",MAX(I11);""firstcolor"",""7dada9""})"),"")
H10: Monthly Expenses | I10: Monthly Income
H11: =SUM(I86,L38) -> 3001 | I11: =F42 -> 3570
G15: Spendable: | I15: =I26 -> 18.706849 | M15: Savings Goal
F18: =" "&'Back Door'!J8&" It's "&text(today(), "dddd, mmmm d")&" there are "&'Back Door'!J5&" days left in this month! You have "&'Back Door'!I18&" payments still due this month!" -> ☕ Good morning! It's Monday, August 17 there are 14 days left in this month! You have 0 payments still due this month!
G23: INSTRUCTIONS FOUND HERE
G25: Calculate spendable using: | I25: Daily
G26: =I25 -> Daily | H26: Spendable: | I26: =(IF(G26="Pay Period", if(D38="","Select a Pay Schedule", if(D38="Weekly", ((I11-H11)*12)/52, if(D38="Bi-Weekly", (((I11-H11)*12)/52)*2,if(D38="Monthly",(I11-H11), if(D38="Bi-Monthly",((I11-H11)*12/24),"bloop"))))),((I11-H11)*12)/365)) -> 18.706849
H28: Weekly Spendable: | I28: =((I11-H11)*12)/52 -> 131.30769
H29: Monthly Spendable: | I29: =(I11-H11) -> 569
G31: Monthly Savings:
G32: =if(D38="", "Select a Pay Schedule",if(D38="Weekly", (((((F39+F40))*52)/12)*(F41/100)), if(D38="Bi-Weekly", ((((((F39)+F40))*24)/12)*(F41/100)), if(D38="Monthly",((F39+F40)*(F41/100)),if(D38="Bi-Monthly",(((F39-F40)*2)*(F41/100))))))) -> 630
C35: Income: | I35: Credit Card Summary:
D37: Pay Schedule: | J37: # of Cards: | L37: =Countif('Credit Card Tracker'!H13:H59,">0") -> 2
D38: Bi-Monthly | J38: Monthly Payments: | L38: =SUM('Credit Card Tracker'!H13:H59) -> 201
D39: Net Income: | F39: 2100
D40: Extra Regular Income: | F40: 0
D41: Monthly Savings: | F41: 15
D42: Total Monthly Income: | F42: =if(D38="", "Select a Pay Schedule",if(D38="Weekly",(((F39+F40)*52/12)-G32), if(D38="Bi-Weekly", (((((F39+F40)*52)/2)/12)-G32), if(D38="Monthly",((F39+F40)-G32),if(D38="Bi-Monthly",(((F39+F40)*2)-G32)))))) -> 3570
B48: Expenses
D50: Change My Name 1 | F50: Due Date | G50: Paid? | J50: Change My Name 4 | L50: Due Date | M50: Paid?
C51: Rent | E51: 1000 | F51: 1 | G51: TRUE | I51: rental | K51: 50 | L51: 13 | M51: FALSE
C52: Electric | E52: 100 | F52: 15 | G52: FALSE | I52: cats | K52: 200 | L52: 15 | M52: TRUE
C53: Phone | E53: 80 | G53: FALSE | M53: FALSE
G54: FALSE | M54: FALSE
G55: FALSE | M55: FALSE
G56: FALSE | M56: FALSE
G57: FALSE | M57: FALSE
G58: FALSE | M58: FALSE
D59: Total | E59: =SUM(E51:E58) -> 1180 | J59: Total | K59: =SUM(K51:K58) -> 250
D61: Change My Name 2 | F61: Due Date | J61: Change My Name 5 | L61: Due Date
C62: groceries | E62: 400 | G62: FALSE | I62: Loans | K62: 400 | L62: 17 | M62: FALSE
C63: lunch | E63: 250 | G63: FALSE | I63: Train pass | K63: 50 | M63: FALSE
G64: FALSE | M64: FALSE
G65: FALSE | M65: FALSE
G66: FALSE | M66: FALSE
G67: FALSE | M67: FALSE
G68: FALSE | M68: FALSE
G69: FALSE | M69: FALSE
...

Sheet Am I over Budget
A1: Am I over Budget???
B5: Name | C5: Budget | D5: Spending
B6: Electric | C6: =IFERROR((VLOOKUP(B6,('Back Door'!$M$2:$N$47),2,0)),"") -> 100 | D6: =if(B6 = "", "",(Sumif($C$16:$C$86,"*"& B6 & "*",$D$16:$D$86))) -> 90 | E6: =IFERROR(__xludf.DUMMYFUNCTION("IFERROR(SPARKLINE(D6, {""charttype"",""bar"";""max"",C6;""min"", 0;""color1"", IF(D6<C6,""bbdba7"",IF(D6>C6,""f59c95"",""f2e7b1""))}),""Select a category"")"),"") | F6: ಠ_ಠ
B7: bubble tea | C7: =IFERROR((VLOOKUP(B7,('Back Door'!$M$2:$N$47),2,0)),"") -> 100 | D7: =if(B7 = "", "",(Sumif($C$16:$C$86,"*"& B7 & "*",$D$16:$D$86))) -> 50 | E7: =IFERROR(__xludf.DUMMYFUNCTION("IFERROR(SPARKLINE(D7, {""charttype"",""bar"";""max"",C7;""min"", 0;""color1"", IF(D7<C7,""bbdba7"",IF(D7>C7,""f59c95"",""f2e7b1""))}),""Select a category"")"),"") | F7: ಠ_ಠ
B8: lunch | C8: =IFERROR((VLOOKUP(B8,('Back Door'!$M$2:$N$47),2,0)),"") -> 250 | D8: =if(B8 = "", "",(Sumif($C$16:$C$86,"*"& B8 & "*",$D$16:$D$86))) -> 300 | E8: =IFERROR(__xludf.DUMMYFUNCTION("IFERROR(SPARKLINE(D8, {""charttype"",""bar"";""max"",C8;""min"", 0;""color1"", IF(D8<C8,""bbdba7"",IF(D8>C8,""f59c95"",""f2e7b1""))}),""Select a category"")"),"") | F8: ಠ_ಠ
B9: Electric | C9: =IFERROR((VLOOKUP(B9,('Back Door'!$M$2:$N$47),2,0)),"") -> 100 | D9: =if(B9 = "", "",(Sumif($C$16:$C$86,"*"& B9 & "*",$D$16:$D$86))) -> 90 | E9: =IFERROR(__xludf.DUMMYFUNCTION("IFERROR(SPARKLINE(D9, {""charttype"",""bar"";""max"",C9;""min"", 0;""color1"", IF(D9<C9,""bbdba7"",IF(D9>C9,""f59c95"",""f2e7b1""))}),""Select a category"")"),"") | F9: ಠ_ಠ
C10: =IFERROR((VLOOKUP(B10,('Back Door'!$M$2:$N$47),2,0)),"") | D10: =if(B10 = "", "",(Sumif($C$16:$C$86,"*"& B10 & "*",$D$16:$D$86))) | E10: =IFERROR(__xludf.DUMMYFUNCTION("IFERROR(SPARKLINE(D10, {""charttype"",""bar"";""max"",C10;""min"", 0;""color1"", IF(D10<C10,""bbdba7"",IF(D10>C10,""f59c95"",""f2e7b1""))}),""Select a category"")"),"Select a category") -> Select a category | F10: ಠ_ಠ
C11: =IFERROR((VLOOKUP(B11,('Back Door'!$M$2:$N$47),2,0)),"") | D11: =if(B11 = "", "",(Sumif($C$16:$C$86,"*"& B11 & "*",$D$16:$D$86))) | E11: =IFERROR(__xludf.DUMMYFUNCTION("IFERROR(SPARKLINE(D11, {""charttype"",""bar"";""max"",C11;""min"", 0;""color1"", IF(D11<C11,""bbdba7"",IF(D11>C11,""f59c95"",""f2e7b1""))}),""Select a category"")"),"Select a category") -> Select a category | F11: ಠ_ಠ
C12: =IFERROR((VLOOKUP(B12,('Back Door'!$M$2:$N$47),2,0)),"") | D12: =if(B12 = "", "",(Sumif($C$16:$C$86,"*"& B12 & "*",$D$16:$D$86))) | E12: =IFERROR(__xludf.DUMMYFUNCTION("IFERROR(SPARKLINE(D12, {""charttype"",""bar"";""max"",C12;""min"", 0;""color1"", IF(D12<C12,""bbdba7"",IF(D12>C12,""f59c95"",""f2e7b1""))}),""Select a category"")"),"Select a category") -> Select a category | F12: ಠ_ಠ
F13: ಠ_ಠ
B15: Date | C15: Category | D15: Spent | E15: Note
B16: 44322 | C16: Electric | D16: 90 | E16: We did it reddit
B17: 44693 | C17: bubble tea | D17: 50
B18: 44701 | C18: lunch | D18: 300 | E18: oh shit o fuk

Sheet Credit Card Tracker
A1: Credit Card Tracker
A3: Total Monthly Payments:
B4: =SUM(H13:H59) -> 201
A5: Highest Balance:
B6: =VLOOKUP(C6,E10:K59,7,fALSE) -> Whew | C6: =MAX(E13:E59) -> 1043
A7: Lowest balance:
B8: =VLOOKUP(C8,E12:K59,7,fALSE) -> Secured | C8: =MIN(E13:E59) -> 0
A9: Closest to Pay Off:
B10: =VLOOKUP(C10,J13:K59,2,fALSE) -> Secured | C10: =Min(J13:J59) -> 0
A12: Card Name | B12: Bank | C12: Card Limit | D12: Annual Fee | E12: Balance | F12: Interest Rate | G12: Interest Only Payment | H12: Monthly Payment | I12: Total Interest Paid | J12: Months to Pay off
A13: Whew | B13: Bank od America | C13: 2000 | D13: 36 | E13: 1043 | F13: 0.2524 | G13: =(E13*F13)/12 -> 21.937767 | H13: 200 | I13: {=IF(ISBLANK(H13:H59),,J13:J59*H13:H59-E13:E59)} -> 73.341211 | J13: {=IF(ISBLANK(H13:H59),,NPER(F13:F59/12,H13:H59,-E13:E59))} -> 5.5817061 | K13: =A13 -> Whew
A14: Secured | B14: Capital One | C14: 551 | D14: 0 | E14: 0 | F14: 0.2324 | G14: =(E14*F14)/12 -> 0 | H14: 1 | I14: 0 | J14: 0 | K14: =A14 -> Secured
K15: =A15
K16: =A16
K17: =A17
K18: =A18
K19: =A19
K20: =A20
K21: =A21
K22: =A22
K23: =A23
K24: =A24
K25: =A25
K26: =A26
... K59: =A59

Sheet Stonks
B1: Stonks Tracker
B6: Ticker | D6: Shares Owned | E6: Buy Price | F6: Current price | G6: % change | H6: Current value | I6: $ up/down | J6: Yearly Trend | M6: Today's change
B7: VXE | D7: 2053 | E7: 90 | F7: =IFERROR(__xludf.DUMMYFUNCTION("IF(ISBLANK(B7),,IFERROR(GOOGLEFINANCE(B7)))"),"") | G7: {=IF(ISBLANK(B7:B22),,F7:F22/E7:E22-100%)} -> -1 | H7: {=IF(ISBLANK(B7:B22),,D7:D22*F7:F22)} -> 0 | I7: {=IF(ISBLANK(B7:B22),,H7:H22-(D7:D22*E7:E22))} -> -184770 | J7: =IFERROR(__xludf.DUMMYFUNCTION("IF(ISBLANK(B7),,IFERROR(SPARKLINE(GOOGLEFINANCE(B7,""price"",TODAY()-365,TODAY(),""daily""),{""charttype"",""line"";""linewidth"",1;""color"",""#88d4c3""})))"),"") | M7: =IFERROR(__xludf.DUMMYFUNCTION("IFERROR(IF(ISBLANK(B7),,GOOGLEFINANCE(B7, ""changepct"")/100))"),"")
B8: BND | D8: 308 | E8: 7.02 | F8: =IFERROR(__xludf.DUMMYFUNCTION("IF(ISBLANK(B8),,IFERROR(GOOGLEFINANCE(B8)))"),72.31) -> 72.31 | G8: 9.3005698 | H8: 22271.48 | I8: 20109.32 | J8: =IFERROR(__xludf.DUMMYFUNCTION("IF(ISBLANK(B8),,IFERROR(SPARKLINE(GOOGLEFINANCE(B8,""price"",TODAY()-365,TODAY(),""daily""),{""charttype"",""line"";""linewidth"",1;""color"",""#88d4c3""})))"),"") | M8: =IFERROR(__xludf.DUMMYFUNCTION("IFERROR(IF(ISBLANK(B8),,GOOGLEFINANCE(B8, ""changepct"")/100))"),0.0) -> 0
F9: =IFERROR(__xludf.DUMMYFUNCTION("IF(ISBLANK(B9),,IFERROR(GOOGLEFINANCE(B9)))"),"") | J9: =IFERROR(__xludf.DUMMYFUNCTION("IF(ISBLANK(B9),,IFERROR(SPARKLINE(GOOGLEFINANCE(B9,""price"",TODAY()-365,TODAY(),""daily""),{""charttype"",""line"";""linewidth"",1;""color"",""#88d4c3""})))"),"") | M9: =IFERROR(__xludf.DUMMYFUNCTION("IFERROR(IF(ISBLANK(B9),,GOOGLEFINANCE(B9, ""changepct"")/100))"),"")
F10: =IFERROR(__xludf.DUMMYFUNCTION("IF(ISBLANK(B10),,IFERROR(GOOGLEFINANCE(B10)))"),"") | J10: =IFERROR(__xludf.DUMMYFUNCTION("IF(ISBLANK(B10),,IFERROR(SPARKLINE(GOOGLEFINANCE(B10,""price"",TODAY()-365,TODAY(),""daily""),{""charttype"",""line"";""linewidth"",1;""color"",""#88d4c3""})))"),"") | M10: =IFERROR(__xludf.DUMMYFUNCTION("IFERROR(IF(ISBLANK(B10),,GOOGLEFINANCE(B10, ""changepct"")/100))"),"")
F11: =IFERROR(__xludf.DUMMYFUNCTION("IF(ISBLANK(B11),,IFERROR(GOOGLEFINANCE(B11)))"),"") | J11: =IFERROR(__xludf.DUMMYFUNCTION("IF(ISBLANK(B11),,IFERROR(SPARKLINE(GOOGLEFINANCE(B11,""price"",TODAY()-365,TODAY(),""daily""),{""charttype"",""line"";""linewidth"",1;""color"",""#88d4c3""})))"),"") | M11: =IFERROR(__xludf.DUMMYFUNCTION("IFERROR(IF(ISBLANK(B11),,GOOGLEFINANCE(B11, ""changepct"")/100))"),"")
F12: =IFERROR(__xludf.DUMMYFUNCTION("IF(ISBLANK(B12),,IFERROR(GOOGLEFINANCE(B12)))"),"") | J12: =IFERROR(__xludf.DUMMYFUNCTION("IF(ISBLANK(B12),,IFERROR(SPARKLINE(GOOGLEFINANCE(B12,""price"",TODAY()-365,TODAY(),""daily""),{""charttype"",""line"";""linewidth"",1;""color"",""#88d4c3""})))"),"") | M12: =IFERROR(__xludf.DUMMYFUNCTION("IFERROR(IF(ISBLANK(B12),,GOOGLEFINANCE(B12, ""changepct"")/100))"),"")
F13: =IFERROR(__xludf.DUMMYFUNCTION("IF(ISBLANK(B13),,IFERROR(GOOGLEFINANCE(B13)))"),"") | J13: =IFERROR(__xludf.DUMMYFUNCTION("IF(ISBLANK(B13),,IFERROR(SPARKLINE(GOOGLEFINANCE(B13,""price"",TODAY()-365,TODAY(),""daily""),{""charttype"",""line"";""linewidth"",1;""color"",""#88d4c3""})))"),"") | M13: =IFERROR(__xludf.DUMMYFUNCTION("IFERROR(IF(ISBLANK(B13),,GOOGLEFINANCE(B13, ""changepct"")/100))"),"")
F14: =IFERROR(__xludf.DUMMYFUNCTION("IF(ISBLANK(B14),,IFERROR(GOOGLEFINANCE(B14)))"),"") | J14: =IFERROR(__xludf.DUMMYFUNCTION("IF(ISBLANK(B14),,IFERROR(SPARKLINE(GOOGLEFINANCE(B14,""price"",TODAY()-365,TODAY(),""daily""),{""charttype"",""line"";""linewidth"",1;""color"",""#88d4c3""})))"),"") | M14: =IFERROR(__xludf.DUMMYFUNCTION("IFERROR(IF(ISBLANK(B14),,GOOGLEFINANCE(B14, ""changepct"")/100))"),"")
F15: =IFERROR(__xludf.DUMMYFUNCTION("IF(ISBLANK(B15),,IFERROR(GOOGLEFINANCE(B15)))"),"") | J15: =IFERROR(__xludf.DUMMYFUNCTION("IF(ISBLANK(B15),,IFERROR(SPARKLINE(GOOGLEFINANCE(B15,""price"",TODAY()-365,TODAY(),""daily""),{""charttype"",""line"";""linewidth"",1;""color"",""#88d4c3""})))"),"") | M15: =IFERROR(__xludf.DUMMYFUNCTION("IFERROR(IF(ISBLANK(B15),,GOOGLEFINANCE(B15, ""changepct"")/100))"),"")
F16: =IFERROR(__xludf.DUMMYFUNCTION("IF(ISBLANK(B16),,IFERROR(GOOGLEFINANCE(B16)))"),"") | J16: =IFERROR(__xludf.DUMMYFUNCTION("IF(ISBLANK(B16),,IFERROR(SPARKLINE(GOOGLEFINANCE(B16,""price"",TODAY()-365,TODAY(),""daily""),{""charttype"",""line"";""linewidth"",1;""color"",""#88d4c3""})))"),"") | M16: =IFERROR(__xludf.DUMMYFUNCTION("IFERROR(IF(ISBLANK(B16),,GOOGLEFINANCE(B16, ""changepct"")/100))"),"")
F17: =IFERROR(__xludf.DUMMYFUNCTION("IF(ISBLANK(B17),,IFERROR(GOOGLEFINANCE(B17)))"),"") | J17: =IFERROR(__xludf.DUMMYFUNCTION("IF(ISBLANK(B17),,IFERROR(SPARKLINE(GOOGLEFINANCE(B17,""price"",TODAY()-365,TODAY(),""daily""),{""charttype"",""line"";""linewidth"",1;""color"",""#88d4c3""})))"),"") | M17: =IFERROR(__xludf.DUMMYFUNCTION("IFERROR(IF(ISBLANK(B17),,GOOGLEFINANCE(B17, ""changepct"")/100))"),"")
F18: =IFERROR(__xludf.DUMMYFUNCTION("IF(ISBLANK(B18),,IFERROR(GOOGLEFINANCE(B18)))"),"") | J18: =IFERROR(__xludf.DUMMYFUNCTION("IF(ISBLANK(B18),,IFERROR(SPARKLINE(GOOGLEFINANCE(B18,""price"",TODAY()-365,TODAY(),""daily""),{""charttype"",""line"";""linewidth"",1;""color"",""#88d4c3""})))"),"") | M18: =IFERROR(__xludf.DUMMYFUNCTION("IFERROR(IF(ISBLANK(B18),,GOOGLEFINANCE(B18, ""changepct"")/100))"),"")
F19: =IFERROR(__xludf.DUMMYFUNCTION("IF(ISBLANK(B19),,IFERROR(GOOGLEFINANCE(B19)))"),"") | J19: =IFERROR(__xludf.DUMMYFUNCTION("IF(ISBLANK(B19),,IFERROR(SPARKLINE(GOOGLEFINANCE(B19,""price"",TODAY()-365,TODAY(),""daily""),{""charttype"",""line"";""linewidth"",1;""color"",""#88d4c3""})))"),"") | M19: =IFERROR(__xludf.DUMMYFUNCTION("IFERROR(IF(ISBLANK(B19),,GOOGLEFINANCE(B19, ""changepct"")/100))"),"")
F20: =IFERROR(__xludf.DUMMYFUNCTION("IF(ISBLANK(B20),,IFERROR(GOOGLEFINANCE(B20)))"),"") | J20: =IFERROR(__xludf.DUMMYFUNCTION("IF(ISBLANK(B20),,IFERROR(SPARKLINE(GOOGLEFINANCE(B20,""price"",TODAY()-365,TODAY(),""daily""),{""charttype"",""line"";""linewidth"",1;""color"",""#88d4c3""})))"),"") | M20: =IFERROR(__xludf.DUMMYFUNCTION("IFERROR(IF(ISBLANK(B20),,GOOGLEFINANCE(B20, ""changepct"")/100))"),"")

Sheet Loanward Bound
A1: Interest Calculator
G6: Loan Amount | I6: 40000
G7: Annual Interest Rate | I7: 0.06
G8: Repaymentperiod (years) | I8: 8
G9: Monthly Payment Amount | I9: =PMT(I7/12,I8*12,-I6) -> 525.65721
D11: Repayment Period (Years)
D12: 1 | E12: =D12+1 -> 2 | F12: =E12+1 -> 3 | G12: =F12+1 -> 4 | H12: =G12+1 -> 5 | I12: =H12+1 -> 6 | J12: =I12+1 -> 7 | K12: =J12+1 -> 8 | L12: =K12+1 -> 9 | M12: =L12+1 -> 10
C13: 0.04 | D13: =PMT($C13/12,D$12*12,-$I$6) -> 3405.9962 | E13: =PMT($C13/12,E$12*12,-$I$6) -> 1736.9969 | F13: =PMT($C13/12,F$12*12,-$I$6) -> 1180.9594 | G13: =PMT($C13/12,G$12*12,-$I$6) -> 903.16219 | H13: =PMT($C13/12,H$12*12,-$I$6) -> 736.66088 | I13: =PMT($C13/12,I$12*12,-$I$6) -> 625.80732 | J13: =PMT($C13/12,J$12*12,-$I$6) -> 546.75225 | K13: =PMT($C13/12,K$12*12,-$I$6) -> 487.57101 | ... M13: =PMT($C13/12,M$12*12,-$I$6) -> 404.98055
C14: 0.045 | D14: =PMT($C14/12,D$12*12,-$I$6) -> 3415.1409 | E14: =PMT($C14/12,E$12*12,-$I$6) -> 1745.9125 | F14: =PMT($C14/12,F$12*12,-$I$6) -> 1189.877 | G14: =PMT($C14/12,G$12*12,-$I$6) -> 912.13944 | H14: =PMT($C14/12,H$12*12,-$I$6) -> 745.72077 | I14: =PMT($C14/12,I$12*12,-$I$6) -> 634.96119 | J14: =PMT($C14/12,J$12*12,-$I$6) -> 556.00645 | K14: =PMT($C14/12,K$12*12,-$I$6) -> 496.92938 | ... M14: =PMT($C14/12,M$12*12,-$I$6) -> 414.55363
C15: 0.05 | D15: =PMT($C15/12,D$12*12,-$I$6) -> 3424.2993 | E15: =PMT($C15/12,E$12*12,-$I$6) -> 1754.8556 | F15: =PMT($C15/12,F$12*12,-$I$6) -> 1198.8359 | G15: =PMT($C15/12,G$12*12,-$I$6) -> 921.17174 | H15: =PMT($C15/12,H$12*12,-$I$6) -> 754.84935 | I15: =PMT($C15/12,I$12*12,-$I$6) -> 644.19731 | J15: =PMT($C15/12,J$12*12,-$I$6) -> 565.35636 | K15: =PMT($C15/12,K$12*12,-$I$6) -> 506.3968 | ... M15: =PMT($C15/12,M$12*12,-$I$6) -> 424.26206
C16: 0.055 | D16: =PMT($C16/12,D$12*12,-$I$6) -> 3433.4714 | E16: =PMT($C16/12,E$12*12,-$I$6) -> 1763.8262 | F16: =PMT($C16/12,F$12*12,-$I$6) -> 1207.8361 | G16: =PMT($C16/12,G$12*12,-$I$6) -> 930.25901 | H16: =PMT($C16/12,H$12*12,-$I$6) -> 764.04649 | I16: =PMT($C16/12,I$12*12,-$I$6) -> 653.51548 | J16: =PMT($C16/12,J$12*12,-$I$6) -> 574.80171 | K16: =PMT($C16/12,K$12*12,-$I$6) -> 515.97289 | ... M16: =PMT($C16/12,M$12*12,-$I$6) -> 434.10511
C17: 0.06 | D17: =PMT($C17/12,D$12*12,-$I$6) -> 3442.6572 | E17: =PMT($C17/12,E$12*12,-$I$6) -> 1772.8244 | F17: =PMT($C17/12,F$12*12,-$I$6) -> 1216.8775 | G17: =PMT($C17/12,G$12*12,-$I$6) -> 939.40116 | H17: =PMT($C17/12,H$12*12,-$I$6) -> 773.31206 | I17: =PMT($C17/12,I$12*12,-$I$6) -> 662.91552 | J17: =PMT($C17/12,J$12*12,-$I$6) -> 584.34218 | K17: =PMT($C17/12,K$12*12,-$I$6) -> 525.65721 | ... M17: =PMT($C17/12,M$12*12,-$I$6) -> 444.08201
C18: 0.065 | D18: =PMT($C18/12,D$12*12,-$I$6) -> 3451.8567 | E18: =PMT($C18/12,E$12*12,-$I$6) -> 1781.8501 | F18: =PMT($C18/12,F$12*12,-$I$6) -> 1225.9601 | G18: =PMT($C18/12,G$12*12,-$I$6) -> 948.59812 | H18: =PMT($C18/12,H$12*12,-$I$6) -> 782.64593 | I18: =PMT($C18/12,I$12*12,-$I$6) -> 672.39719 | J18: =PMT($C18/12,J$12*12,-$I$6) -> 593.97746 | K18: =PMT($C18/12,K$12*12,-$I$6) -> 535.4493 | ... M18: =PMT($C18/12,M$12*12,-$I$6) -> 454.19191
C19: 0.07 | D19: =PMT($C19/12,D$12*12,-$I$6) -> 3461.0698 | E19: =PMT($C19/12,E$12*12,-$I$6) -> 1790.9032 | F19: =PMT($C19/12,F$12*12,-$I$6) -> 1235.0839 | G19: =PMT($C19/12,G$12*12,-$I$6) -> 957.84979 | H19: =PMT($C19/12,H$12*12,-$I$6) -> 792.04794 | I19: =PMT($C19/12,I$12*12,-$I$6) -> 681.96026 | J19: =PMT($C19/12,J$12*12,-$I$6) -> 603.7072 | K19: =PMT($C19/12,K$12*12,-$I$6) -> 545.34868 | ... M19: =PMT($C19/12,M$12*12,-$I$6) -> 464.43392
D21: Total Interest Paid
D22: 1 | E22: =D22+1 -> 2 | F22: =E22+1 -> 3 | G22: =F22+1 -> 4 | H22: =G22+1 -> 5 | I22: =H22+1 -> 6 | J22: =I22+1 -> 7 | K22: =J22+1 -> 8 | L22: =K22+1 -> 9 | M22: =L22+1 -> 10
C23: 0.04 | D23: =D13*D$12*12-$I$6 -> 871.95401 | E23: =E13*E$12*12-$I$6 -> 1687.9253 | F23: =F13*F$12*12-$I$6 -> 2514.5384 | G23: =G13*G$12*12-$I$6 -> 3351.7849 | H23: =H13*H$12*12-$I$6 -> 4199.6529 | I23: =I13*I$12*12-$I$6 -> 5058.1272 | J23: =J13*J$12*12-$I$6 -> 5927.1893 | K23: =K13*K$12*12-$I$6 -> 6806.8172 | ... M23: =M13*M$12*12-$I$6 -> 8597.6663
C24: 0.045 | D24: =D14*D$12*12-$I$6 -> 981.69036 | E24: =E14*E$12*12-$I$6 -> 1901.8991 | F24: =F14*F$12*12-$I$6 -> 2835.5712 | G24: =G14*G$12*12-$I$6 -> 3782.6933 | H24: =H14*H$12*12-$I$6 -> 4743.2462 | I24: =I14*I$12*12-$I$6 -> 5717.2056 | J24: =J14*J$12*12-$I$6 -> 6704.542 | K24: =K14*K$12*12-$I$6 -> 7705.2202 | ... M24: =M14*M$12*12-$I$6 -> 9746.4362
C25: 0.05 | D25: =D15*D$12*12-$I$6 -> 1091.5913 | E25: =E15*E$12*12-$I$6 -> 2116.5341 | F25: =F15*F$12*12-$I$6 -> 3158.0918 | G25: =G15*G$12*12-$I$6 -> 4216.2437 | H25: =H15*H$12*12-$I$6 -> 5290.9607 | I25: =I15*I$12*12-$I$6 -> 6382.2061 | J25: =J15*J$12*12-$I$6 -> 7489.9345 | K25: =K15*K$12*12-$I$6 -> 8614.0928 | ... M25: =M15*M$12*12-$I$6 -> 10911.447
C26: 0.055 | D26: =D16*D$12*12-$I$6 -> 1201.6566 | E26: =E16*E$12*12-$I$6 -> 2331.8299 | F26: =F16*F$12*12-$I$6 -> 3482.0986 | G26: =G16*G$12*12-$I$6 -> 4652.4324 | H26: =H16*H$12*12-$I$6 -> 5842.7892 | I26: =I16*I$12*12-$I$6 -> 7053.1148 | J26: =J16*J$12*12-$I$6 -> 8283.3433 | K26: =K16*K$12*12-$I$6 -> 9533.3972 | ... M26: =M16*M$12*12-$I$6 -> 12092.613
C27: 0.06 | D27: =D17*D$12*12-$I$6 -> 1311.8863 | E27: =E17*E$12*12-$I$6 -> 2547.7858 | F27: =F17*F$12*12-$I$6 -> 3807.5899 | G27: =G17*G$12*12-$I$6 -> 5091.2558 | H27: =H17*H$12*12-$I$6 -> 6398.7237 | I27: =I17*I$12*12-$I$6 -> 7729.9171 | J27: =J17*J$12*12-$I$6 -> 9084.7431 | K27: =K17*K$12*12-$I$6 -> 10463.092 | ... M27: =M17*M$12*12-$I$6 -> 13289.841
C28: 0.065 | D28: =D18*D$12*12-$I$6 -> 1422.2801 | E28: =E18*E$12*12-$I$6 -> 2764.4014 | F28: =F18*F$12*12-$I$6 -> 4134.5641 | G28: =G18*G$12*12-$I$6 -> 5532.7096 | H28: =H18*H$12*12-$I$6 -> 6958.7557 | I28: =I18*I$12*12-$I$6 -> 8412.5973 | J28: =J18*J$12*12-$I$6 -> 9894.1065 | K28: =K18*K$12*12-$I$6 -> 11403.133 | ... M28: =M18*M$12*12-$I$6 -> 14503.029
C29: 0.07 | D29: =D19*D$12*12-$I$6 -> 1532.8381 | E29: =E19*E$12*12-$I$6 -> 2981.6759 | F29: =F19*F$12*12-$I$6 -> 4463.0195 | G29: =G19*G$12*12-$I$6 -> 5976.7898 | H29: =H19*H$12*12-$I$6 -> 7522.8765 | I29: =I19*I$12*12-$I$6 -> 9101.1386 | J29: =J19*J$12*12-$I$6 -> 10711.405 | K29: =K19*K$12*12-$I$6 -> 12353.474 | ... M29: =M19*M$12*12-$I$6 -> 15732.07

Sheet Savings Goal Calculator
A1: Savings goal Tracker
D9: Date Started Saving | E9: 44652
D10: Beginning Balance | E10: 100
D11: Monthly Savings | E11: =Budget!G32 -> 630
D12: Savings Goal | E12: 4000
D13: Current Balance: | E13: =E10+(E11*(Datedif(E9,'Back Door'!J3,"M")))+SUM(D24:D85) -> 32560
D15: Months to Goal | E15: =E12/E11 -> 6.3492063
B21: Extra Savings Adjustments
B23: Name | C23: Date: | D23: Amount Adjusted: | E23: Notes:
B24: Gift | C24: 44702 | D24: 600
B25: Car problems | D25: -900

Sheet Savings Percentage Calculator
A2: Savings Percentage Calculator
B5: Use this to calculate the amount you want to save as a percentage of your income- to make it easier to put into the Budget!
B7: Income:
B8: =Budget!F39 -> 2100
B9: Savings
B10: 250
B11: Percent savings
B12: =(B10/B8) -> 0.11904762
B14: Monthly Saving amount:
B15: =B10 -> 250
A17: =if(B16=TRUE,"!", " " ) | E17: =if(B16=TRUE,"!", " " )

Sheet Large Purchase Calculator
A2: Large Purchase Calculator
B5: Item:
B6: Vic20
B7: Price
B8: 300
B9: Months until purchase
B10: 3
B12: Monthly Saving amount:
B13: =B8/B10 -> 100
B14: TRUE | C14: Adjust Budget?
A15: =if(B14=TRUE,"!", " " ) -> ! | B15: =if(B14=TRUE,"Your budget has been automatically adjusted to add this expense! please go check your budget!", " " ) -> Your budget has been automatically adjusted to add this expense! please go check your budget! | E15: =if(B14=TRUE,"!", " " ) -> !

Sheet Back Door
A2: Pay Schedule: | C2: Savings Percentages: | D2: Savings: | E2: Due Date | F2: Beginning of the month | G2: End Of the Month | M2: =Budget!C51 -> Rent | N2: =Budget!E51 -> 1000
A3: Weekly | C3: 5 | D3: =Budget!F39*(Budget!F41/100) -> 315 | E3: n/a | F3: =SUM(SUMIF(Budget!F51:F58,"<15",Budget!E51:E58),SUMIF(Budget!F62:F69,"<15",Budget!E62:E69),SUMIF(Budget!F73:F80,"<15",Budget!E73:E80), SUMIF(Budget!L51:L58,"<15",Budget!K51:K58),SUMIF(Budget!L62:L69,"<15",Budget!K62:K69),SUMIF(Budget!L73:L83,"<15",Budget!K73:K83))+F5 -> 1610 | G3: =SUM(SUMIF(Budget!F51:F58,">15",Budget!E51:E58),SUMIF(Budget!F62:F69,">15",Budget!E62:E69),SUMIF(Budget!F73:F80,">15",Budget!E73:E80), SUMIF(Budget!L51:L58,">15",Budget!K51:K58),SUMIF(Budget!L62:L69,">15",Budget!K62:K69),SUMIF(Budget!L73:L83,">15",Budget!K73:K83))+F5 -> 940 | I3: Today | J3: =TODAY() -> 46251 | K3: =DAY(TODAY()) -> 17 | M3: =Budget!C52 -> Electric | N3: =Budget!E52 -> 100
A4: Bi-Weekly | C4: 10 | E4: 1 | I4: Last Day Month | J4: =EOMONTH(J3, 0) -> 46265 | K4: =DAY(EOMONTH(J3, 0)) -> 31 | M4: =Budget!C53 -> Phone | N4: =Budget!E53 -> 80
A5: Bi-Monthly | C5: 15 | E5: 2 | F5: =SUM(SUMIF(Budget!F51:F58,"",Budget!E51:E58),SUMIF(Budget!F62:F69,"",Budget!E62:E69),SUMIF(Budget!F73:F80,"",Budget!E73:E80), SUMIF(Budget!L51:L58,"",Budget!K51:K58),SUMIF(Budget!L62:L69,"<",Budget!K62:K69),SUMIF(Budget!L73:L83,"",Budget!K73:K83))/2 -> 540 | I5: Days left | J5: =DATEDIF(J3,J4,"d") -> 14 | M5: =Budget!C54 | N5: =Budget!E54
A6: Monthly | C6: 20 | E6: 3 | I6: Time | J6: =TEXT(NOW(),"hh:mm") -> 08:47 | M6: =Budget!C55 | N6: =Budget!E55
A7: Payments: | C7: 25 | E7: 4 | I7: Hour | J7: =HOUR(J6) -> 8 | M7: =Budget!C56 | N7: =Budget!E56
C8: 30 | E8: 5 | I8: Welcome | J8: =ifs(J7<12, "☕ Good morning! ",J7<18, "☀️ Good Day! ",J7<24, "🌙 Good evening! ") -> ☕ Good morning! | M8: =Budget!C57 | N8: =Budget!E57
A9: =Budget!D50 -> Change My Name 1 | B9: =SUM(Budget!E51:E58) -> 1180 | C9: 35 | E9: 6 | M9: =Budget!C58 | N9: =Budget!E58
A10: =Budget!J50 -> Change My Name 4 | B10: =SUM(Budget!K51:K58) -> 250 | C10: 40 | E10: 7 | M10: =Budget!C62 -> groceries | N10: =Budget!E62 -> 400
A11: =Budget!D61 -> Change My Name 2 | B11: =SUM(Budget!E62:E69) -> 650 | C11: 45 | E11: 8 | I11: Counts | M11: =Budget!C63 -> lunch | N11: =Budget!E63 -> 250
A12: =Budget!D72 -> Change My Name 3 | B12: =SUM(Budget!E73:E80) -> 70 | C12: 50 | E12: 9 | H12: =Budget!D50 -> Change My Name 1 | I12: =SUM(COUNTIFs(Budget!F51:F58,">"&K3,Budget!F51:F58,"<"&K4)) -> 0 | M12: =Budget!C64 | N12: =Budget!E64
A13: =Budget!J61 -> Change My Name 5 | B13: =SUM(Budget!K62:K69) -> 450 | C13: 55 | E13: 10 | H13: =Budget!J50 -> Change My Name 4 | I13: =COUNTIFs(Budget!L51:L58,">"&K3,Budget!L51:L58,"<"&K4) -> 0 | M13: =Budget!C65 | N13: =Budget!E65
A14: =Budget!J72 -> Change My Name 6 | B14: =SUM(Budget!K73:K77) -> 100 | C14: 60 | E14: 11 | H14: =Budget!D61 -> Change My Name 2 | I14: =COUNTIFs(Budget!F62:F69,">"&K3,Budget!F62:F69,"<"&K4) -> 0 | M14: =Budget!C66 | N14: =Budget!E66
C15: 65 | E15: 12 | H15: =Budget!D72 -> Change My Name 3 | I15: =COUNTIFs(Budget!F73:F80,">"&K3,Budget!F73:F80,"<"&K4) -> 0 | M15: =Budget!C67 | N15: =Budget!E67
C16: 70 | E16: 13 | H16: =Budget!J61 -> Change My Name 5 | I16: =COUNTIFs(Budget!L62:L69,">"&K3,Budget!L62:L69,"<"&K4) -> 0 | M16: =Budget!C68 | N16: =Budget!E68
A17: Calculation: | C17: 75 | E17: 14 | H17: =Budget!J72 -> Change My Name 6 | I17: =COUNTIFs(Budget!L73:L75,">"&K3,Budget!L73:L75,"<"&K4) -> 0 | M17: =Budget!C69 | N17: =Budget!E69
A18: Daily | C18: 80 | E18: 15 | H18: all | I18: =SUM(I12:I17) -> 0 | M18: =Budget!C73 -> Netflix | N18: =Budget!E73 -> 20
A19: Pay Period | C19: 85 | E19: 16 | M19: =Budget!C74 -> Adobe | N19: =Budget!E74 -> 30
C20: 90 | E20: 17 | M20: =Budget!C75 -> Sporitfy | N20: =Budget!E75 -> 10
C21: 95 | E21: 18 | M21: =Budget!C76 -> Youtube Premium | N21: =Budget!E76 -> 10
C22: 0 | E22: 19 | M22: =Budget!C77 | N22: =Budget!E77
E23: 20 | M23: =Budget!C78 | N23: =Budget!E78
A24: Version 1.5 | E24: 21 | M24: =Budget!C79 | N24: =Budget!E79
E25: 22 | M25: =Budget!C80 | N25: =Budget!E80
E26: 23 | M26: =Budget!I51 -> rental | N26: =Budget!K51 -> 50
E27: 24 | M27: =Budget!I52 -> cats | N27: =Budget!K52 -> 200
E28: 25 | M28: =Budget!I53 | N28: =Budget!K53
E29: 26 | M29: =Budget!I54 | N29: =Budget!K54
E30: 27 | M30: =Budget!I55 | N30: =Budget!K55
E31: 28 | M31: =Budget!I56 | N31: =Budget!K56
E32: 29 | M32: =Budget!I57 | N32: =Budget!K57
E33: 30 | M33: =Budget!I58 | N33: =Budget!K58
E34: 31 | M34: =Budget!I62 -> Loans | N34: =Budget!K62 -> 400
M35: =Budget!I63 -> Train pass | N35: =Budget!K63 -> 50
M36: =Budget!I64 | N36: =Budget!K64
M37: =Budget!I65 | N37: =Budget!K65
M38: =Budget!I66 | N38: =Budget!K66
M39: =Budget!I67 | N39: =Budget!K67
M40: =Budget!I68 | N40: =Budget!K68
M41: =Budget!I69 | N41: =Budget!K69
...
