Workbook
Name zsupermetrics_fLccNanwfgLiXwrEPyMK7lYghc956O: RawData!$Q$3:$S$57
Name zsupermetrics_V7D8bLrRAfoX6esl0vHJWHWF99pWbi: RawData!$AD$14:$AP$18
Name zsupermetrics_GollWneUWz9jEtDUFyVzuozqyrZI5L: #REF!
Name zsupermetrics_Wk9OpkHfbIa08VQsgSFGks6won42Al: RawData!$AD$3:$AP$11
Name zsupermetrics_kvlmQeHYoLRFxu7MPFqXAWOlPOyxsL: RawData!$AD$3:$AP$11
Name zsupermetrics_gyCp8tRRFoEWdfvljO6rIOfMXdEkW4: #REF!
Name zsupermetrics_uw1iVztjfTNXySzSwGJchG0T18IGGr: RawData!$B$4:$N$14
Name zsupermetrics_km2MuACEhLAFwFJfnA5ApwBzt3hPwe: RawData!$U$3:$X$57
Name zsupermetrics_ASmWSLVAZpNEZnROjRtjpPnqivXMJN: #REF!
Name zsupermetrics_UtgKARcsNMj6uyu1c7gi9rSlGkbo02: RawData!$AD$14:$AP$18
Name zsupermetrics_KZQmPV9KsXDpnW4edPoTeh3Fsw2SRr: RawData!$Q$3:$S$57
Name zsupermetrics_iUSMhGYLLTsj9TryRGU7Sm2NDc2hWx: RawData!$Z$3:$AB$10
Name zsupermetrics_soCeKLTRN3F2CC1LXhS5l1rb6vSgvB: 'Traffic Dashboard'!$C$36:$D$57
Name zsupermetrics_yKDA3oHGDUToQfWdpDIGFnK1zsGqJ5: RawData!$Z$14:$AB$18
Name zsupermetrics_RHzJaap6zqV7UDnv9dAjBzi4oZhGqU: RawData!$AD$14:$AP$18
Name zsupermetrics_eeHV5bWCGzuMQLdaIWqLH4nB1EeG0X: 'Traffic Dashboard'!$C$35:$D$57
Name zsupermetrics_FfuNxBfh6Qu63V8R3Kw1kwbdVZxXnC: RawData!$Z$3:$AB$10
Name zsupermetrics_wcYOQONrkg7AIVyxgkbrLVOdenvNMt: #REF!
Name zsupermetrics_g2u7LzBOcBOnMs25Y02G12smse96bw: RawData!$U$3:$X$57
Name zsupermetrics_U268zO1zKJ6xCqytJcoL4ZGDgfNQNW: #REF!
Name zsupermetrics_jUJIRk1QmiYNIWGCIvu9jiCymVIG8j: RawData!$AD$14:$AP$18
Name zsupermetrics_sTRoMUOZAQXWv0NLzfN9fUc99BbXDG: #REF!
Name zsupermetrics_CjHVB1rykvTwH3Ee5CzRM1bKS2qX4s: RawData!$B$30:$N$57
Name zsupermetrics_ks8byweTq0ZvMpxgJwm70LXqaGOSQT: #REF!
Name zsupermetrics_dnVG7ifsJOQIutUAC9cQEVGWbAaPF5: RawData!$U$3:$X$57
Name zsupermetrics_refreshAllSilent: SupermetricsQueries!$H$6
Name zsupermetrics_1uIP5Fck3SwdBmsjEq8nCC93kef8Z8: 'Traffic Dashboard'!$C$36:$D$57
Name zsupermetrics_13Ft7VWubS9oaFWaCu1YzWwiXBkdUN: #REF!
Name zsupermetrics_GyUODYVVUwewj3oQpSJE7xqTEX7Ggx: RawData!$B$30:$N$57
Name zsupermetrics_tMVCicIYB1ppWLy2ySJOGFz2GMKNHc: #REF!
Name zsupermetrics_BYTQxLVWfT2A6OvVZPFs4tQupdzuUi: #REF!
Name zsupermetrics_c4NjNoDdq03RshXx5S0zryl3nYdjKd: RawData!$AD$3:$AP$11
Name zsupermetrics_ugJOJpBBq7U9CWlxh8RGscHywuoJzT: #REF!
Name zsupermetrics_bxQwFAuIWtvgf3sCdYhidmLNNyxdLX: 'Traffic Dashboard'!$C$36:$D$57
Name zsupermetrics_PWuqdiW5nwRjIguyJJVAlLhP1F9TJP: RawData!$B$4:$N$14
Name zsupermetrics_uVZdbjHhM3WmfLWpc4KOvqjIwxXjml: 'Traffic Dashboard'!$C$35:$F$55
Name zsupermetrics_xFBn4wQ67lWGGd87jkHjtbcKh1Vahk: RawData!$Z$14:$AB$18
Name zsupermetrics_hssL662pqpyr3WMuJV0IMOiQoobsvd: RawData!$Z$3:$AB$10
Name zsupermetrics_forceRefresh: SupermetricsQueries!$H$4
Name zsupermetrics_VIMlNqyQl10xX5wjZOvkRuBTiXtVkX: RawData!$U$3:$X$57
Name zsupermetrics_9Or905dgXknIiqvzoJYDZrge5SfZDE: RawData!$B$4:$N$14
Name zsupermetrics_jGUP29KhNNfsgMBQBPNraVAN8EAcB3: RawData!$Q$3:$S$57
Name zsupermetrics_ToVzapbdmhXpbzsEU51d9kkMYdy3nb: 'Traffic Dashboard'!$C$35:$F$55
Name zsupermetrics_nJ7FfLFQaYxxEBCZN2VrT9nejM2Y0M: RawData!$Z$3:$AB$10
Name zsupermetrics_YwCJzbBwg2YvC7a9kH3fWuyYiaiebA: RawData!$B$4:$N$14
Name zsupermetrics_7C8ru29Hayl31nx8WfVR4zkEM3vpNj: RawData!$B$30:$N$57
Name zsupermetrics_nIOFMsWoy7w76KI0QncltOGNRf602L: #REF!
Name zsupermetrics_x5fvWsD4aA8V70sf5XI5yNMW9Potso: #REF!
Name zsupermetrics_JhZ48HA7m8494CLO6pMDDsQQVUd8M7: RawData!$AD$3:$AP$11
Name zsupermetrics_OVvwGsyakToQ4EkI9GXwg0KqCP3SNN: RawData!$B$30:$N$57
Name zsupermetrics_refreshAll: SupermetricsQueries!$H$5
Name zsupermetrics_xGNTlt0hZmE6tblxXBR5GITtf2wIpq: #REF!
Name zsupermetrics_xhYP6OpJR7chPxEE9foAjTSo849s1x: #REF!
Name zsupermetrics_r5zSS2OaiNgxCLDtbvwSbMFTQAJygz: RawData!$Z$14:$AB$18
Name zsupermetrics_jXzwJ2FkNqapH6Df01mlX0Wdvtm2a8: #REF!
Name zsupermetrics_b7BrB4EzkxhjSNahg0ktVnW3SpENtX: #REF!
Name zsupermetrics_Td7iyBBkrmCnw5oIQTfCtLJMK0h1z7: #REF!
Name zsupermetrics_xr3gee86n6wWjE3Ot3Eh2EJkYv346Z: #REF!
Name zsupermetrics_27F5mFD7hgHHibPgu6smfn8IBFZvdR: RawData!$Q$3:$S$57
Name zsupermetrics_90qlCaDtCkCRYERzBc3osJeravbZGl: #REF!

Sheet SupermetricsQueries
A1: Supermetrics Queries
A2: specialnewuserflow
A3: All the queries created by Supermetrics are stored here, each in its own row.
H4: 15091053
A5: On this sheet you can:
A6: 1. Modify the parameters of a query. Any changes will be visible when you run a refresh.
A8: 2. Remove a query by deleting its row
A10: 3. Add new queries: type a range address and query parameters, leave the query ID empty. The query will be added when you run a refresh. (Of course, it's much easier to use the sidebar to add new queries.)
A12: 4. Add queries that point to other spreadsheets: follow step 3, but also add a spreadsheet ID (you can see the ID in the URL when you have a file open)
A19: Query ID | C19: Spreadsheet ID | D19: Sheet name | E19: Range address | G19: Created | H19: Updated | I19: Last status | J19: Last refresh ID | K19: Results contain sampled data | M19: Object type | N19: Linked chart ID | O19: Data source | Q19: Date range type | R19: Start date | S19: End date | T19: Compare to | U19: Comparison value type | W19: Accounts/views | X19: Metrics | Y19: Dimensions | Z19: Pivot dimensions | AA19: Filters | AB19: Segment ID | AC19: Sort | AD19: Max rows | AE19: Max pivot categories | AF19: Special settings | AG19: Other parameters | AJ19: Result type | AK19: Language/country | AL19: Translate to | AN19: SQL | AO19: Database name | AP19: Range address (static) | AQ19: Report type | AR19: Scope (Moz) | AS19: Sort (Moz) | AT19: Highlight with colour | AU19: Refresh with user account
A20: paramsID | C20: ssID | D20: sheetName | E20: rangeAddress | G20: created | H20: updated | I20: lastStatus | J20: lastqueryID | K20: sampled | M20: objType | N20: linkedChartID | O20: dataSource | Q20: dateRangeType | R20: startDateString | S20: endDateString | T20: comp | U20: cvt | W20: profiles | X20: metrics | Y20: dimensions | Z20: sd | AA20: filterArr | AB20: segment | AC20: sort | AD20: maxResults | AE20: maxCategories | AF20: specialSettings | AG20: otherParams | AJ20: sds_result_type | AK20: sds_lang | AL20: sds_tolang | AN20: sql | AO20: db_name | AP20: rangeAddressStatic | AQ20: rt | AR20: scopeMZ | AS20: sortMZ | AT20: condform | AU20: authUser
D21: =IFERROR(__xludf.DUMMYFUNCTION("ARRAY_CONSTRAIN(split(CELL(""ADDRESS"",zsupermetrics_YwCJzbBwg2YvC7a9kH3fWuyYiaiebA),""!""),1,1)"),"#NAME?") -> #NAME? | E21: =CELL("ADDRESS",zsupermetrics_YwCJzbBwg2YvC7a9kH3fWuyYiaiebA)&":"&address(row(zsupermetrics_YwCJzbBwg2YvC7a9kH3fWuyYiaiebA)+rows(zsupermetrics_YwCJzbBwg2YvC7a9kH3fWuyYiaiebA)-1,column(zsupermetrics_YwCJzbBwg2YvC7a9kH3fWuyYiaiebA)+COLUMNS(zsupermetrics_YwCJzbBwg2YvC7a9kH3fWuyYiaiebA)-1) -> #NAME? | G21: 43035.622 | H21: 43035.622 | I21: Created successfully | J21: 1509105323283 | K21: FALSE | M21: TABLE | O21: GA | Q21: last12months | X21: ["visitors"] | Y21: ["Medium"] | Z21: ["Yearmonth"] | AA21: [] | AB21: [] | AD21: 10 | AE21: 20 | AF21: [] | AG21: {} | AP21: RawData'!B4:N14
D22: =IFERROR(__xludf.DUMMYFUNCTION("ARRAY_CONSTRAIN(split(CELL(""ADDRESS"",zsupermetrics_jGUP29KhNNfsgMBQBPNraVAN8EAcB3),""!""),1,1)"),"#NAME?") -> #NAME? | E22: =CELL("ADDRESS",zsupermetrics_jGUP29KhNNfsgMBQBPNraVAN8EAcB3)&":"&address(row(zsupermetrics_jGUP29KhNNfsgMBQBPNraVAN8EAcB3)+rows(zsupermetrics_jGUP29KhNNfsgMBQBPNraVAN8EAcB3)-1,column(zsupermetrics_jGUP29KhNNfsgMBQBPNraVAN8EAcB3)+COLUMNS(zsupermetrics_jGUP29KhNNfsgMBQBPNraVAN8EAcB3)-1) -> #NAME? | G22: 43035.622 | H22: 43035.622 | I22: Created successfully | J22: 1509105323283 | K22: FALSE | M22: TABLE | O22: GA | Q22: lastmonth | X22: ["entrances"] | Y22: ["Source","LandingPagePath"] | Z22: [] | AA22: [] | AB22: [] | AD22: 10000 | AF22: [] | AG22: {} | AP22: RawData'!Q3:S3978
D23: =IFERROR(__xludf.DUMMYFUNCTION("ARRAY_CONSTRAIN(split(CELL(""ADDRESS"",zsupermetrics_g2u7LzBOcBOnMs25Y02G12smse96bw),""!""),1,1)"),"#NAME?") -> #NAME? | E23: =CELL("ADDRESS",zsupermetrics_g2u7LzBOcBOnMs25Y02G12smse96bw)&":"&address(row(zsupermetrics_g2u7LzBOcBOnMs25Y02G12smse96bw)+rows(zsupermetrics_g2u7LzBOcBOnMs25Y02G12smse96bw)-1,column(zsupermetrics_g2u7LzBOcBOnMs25Y02G12smse96bw)+COLUMNS(zsupermetrics_g2u7LzBOcBOnMs25Y02G12smse96bw)-1) -> #NAME? | G23: 43035.622 | H23: 43035.622 | I23: Created successfully | J23: 1509105323283 | K23: FALSE | M23: TABLE | O23: GA | Q23: last1months | X23: ["visitors","entrancebouncerate_perc","percentnewvisits_perc"] | Y23: ["Source"] | Z23: [] | AA23: [] | AB23: [] | AD23: 10000 | AF23: [] | AG23: {} | AP23: RawData'!U3:X310
D24: =IFERROR(__xludf.DUMMYFUNCTION("ARRAY_CONSTRAIN(split(CELL(""ADDRESS"",zsupermetrics_nJ7FfLFQaYxxEBCZN2VrT9nejM2Y0M),""!""),1,1)"),"#NAME?") -> #NAME? | E24: =CELL("ADDRESS",zsupermetrics_nJ7FfLFQaYxxEBCZN2VrT9nejM2Y0M)&":"&address(row(zsupermetrics_nJ7FfLFQaYxxEBCZN2VrT9nejM2Y0M)+rows(zsupermetrics_nJ7FfLFQaYxxEBCZN2VrT9nejM2Y0M)-1,column(zsupermetrics_nJ7FfLFQaYxxEBCZN2VrT9nejM2Y0M)+COLUMNS(zsupermetrics_nJ7FfLFQaYxxEBCZN2VrT9nejM2Y0M)-1) -> #NAME? | G24: 43035.622 | H24: 43035.622 | I24: Created successfully | J24: 1509105323283 | K24: FALSE | M24: TABLE | O24: GA | Q24: last1months | T24: prev | U24: perc | X24: ["visitors","visits","entrancebouncerate_perc","percentnewvisits_perc","pageviews","avgtimeonsite_minutes","transactions","transactionrevenue"] | Y24: [] | Z24: [] | AA24: [] | AB24: [] | AD24: 1000 | AE24: 10 | AF24: ["METRICS_IN_ROWS"] | AG24: {} | AP24: RawData'!Z3:AB10
D25: =IFERROR(__xludf.DUMMYFUNCTION("ARRAY_CONSTRAIN(split(CELL(""ADDRESS"",zsupermetrics_yKDA3oHGDUToQfWdpDIGFnK1zsGqJ5),""!""),1,1)"),"#NAME?") -> #NAME? | E25: =CELL("ADDRESS",zsupermetrics_yKDA3oHGDUToQfWdpDIGFnK1zsGqJ5)&":"&address(row(zsupermetrics_yKDA3oHGDUToQfWdpDIGFnK1zsGqJ5)+rows(zsupermetrics_yKDA3oHGDUToQfWdpDIGFnK1zsGqJ5)-1,column(zsupermetrics_yKDA3oHGDUToQfWdpDIGFnK1zsGqJ5)+COLUMNS(zsupermetrics_yKDA3oHGDUToQfWdpDIGFnK1zsGqJ5)-1) -> #NAME? | G25: 43035.622 | H25: 43035.622 | I25: Created successfully | J25: 1509105323283 | K25: FALSE | M25: TABLE | O25: GA | Q25: last1months | T25: prev | U25: perc | X25: ["visitors"] | Y25: ["segmentname"] | Z25: [] | AA25: [] | AB25: ["-13`Tablet Traffic","-14`Mobile Traffic","-102`Converters","-104`Made a Purchase"] | AD25: 50 | AF25: [] | AG25: {} | AP25: RawData'!Z14:AB18
D26: =IFERROR(__xludf.DUMMYFUNCTION("ARRAY_CONSTRAIN(split(CELL(""ADDRESS"",zsupermetrics_Wk9OpkHfbIa08VQsgSFGks6won42Al),""!""),1,1)"),"#NAME?") -> #NAME? | E26: =CELL("ADDRESS",zsupermetrics_Wk9OpkHfbIa08VQsgSFGks6won42Al)&":"&address(row(zsupermetrics_Wk9OpkHfbIa08VQsgSFGks6won42Al)+rows(zsupermetrics_Wk9OpkHfbIa08VQsgSFGks6won42Al)-1,column(zsupermetrics_Wk9OpkHfbIa08VQsgSFGks6won42Al)+COLUMNS(zsupermetrics_Wk9OpkHfbIa08VQsgSFGks6won42Al)-1) -> #NAME? | G26: 43035.622 | H26: 43035.622 | I26: Created successfully | J26: 1509105323283 | K26: FALSE | M26: TABLE | O26: GA | Q26: last12months | X26: ["visitors","visits","entrancebouncerate_perc","percentnewvisits_perc","pageviews","avgtimeonsite_minutes","transactions","transactionrevenue"] | Y26: [] | Z26: ["Yearmonth"] | AA26: [] | AB26: [] | AD26: 10000 | AE26: 20 | AF26: ["METRICS_IN_ROWS"] | AG26: {} | AP26: RawData'!AD3:AP11
D27: =IFERROR(__xludf.DUMMYFUNCTION("ARRAY_CONSTRAIN(split(CELL(""ADDRESS"",zsupermetrics_RHzJaap6zqV7UDnv9dAjBzi4oZhGqU),""!""),1,1)"),"#NAME?") -> #NAME? | E27: =CELL("ADDRESS",zsupermetrics_RHzJaap6zqV7UDnv9dAjBzi4oZhGqU)&":"&address(row(zsupermetrics_RHzJaap6zqV7UDnv9dAjBzi4oZhGqU)+rows(zsupermetrics_RHzJaap6zqV7UDnv9dAjBzi4oZhGqU)-1,column(zsupermetrics_RHzJaap6zqV7UDnv9dAjBzi4oZhGqU)+COLUMNS(zsupermetrics_RHzJaap6zqV7UDnv9dAjBzi4oZhGqU)-1) -> #NAME? | G27: 43035.622 | H27: 43035.622 | I27: Created successfully | J27: 1509105323283 | K27: FALSE | M27: TABLE | O27: GA | Q27: last12months | X27: ["visitors"] | Y27: ["segmentname"] | Z27: ["Yearmonth"] | AA27: [] | AB27: ["-13`Tablet Traffic","-14`Mobile Traffic","-102`Converters","-104`Made a Purchase"] | AD27: 50 | AE27: 20 | AF27: [] | AG27: {} | AP27: RawData'!AD14:AP18
D28: =IFERROR(__xludf.DUMMYFUNCTION("ARRAY_CONSTRAIN(split(CELL(""ADDRESS"",zsupermetrics_GyUODYVVUwewj3oQpSJE7xqTEX7Ggx),""!""),1,1)"),"#NAME?") -> #NAME? | E28: =CELL("ADDRESS",zsupermetrics_GyUODYVVUwewj3oQpSJE7xqTEX7Ggx)&":"&address(row(zsupermetrics_GyUODYVVUwewj3oQpSJE7xqTEX7Ggx)+rows(zsupermetrics_GyUODYVVUwewj3oQpSJE7xqTEX7Ggx)-1,column(zsupermetrics_GyUODYVVUwewj3oQpSJE7xqTEX7Ggx)+COLUMNS(zsupermetrics_GyUODYVVUwewj3oQpSJE7xqTEX7Ggx)-1) -> #NAME? | G28: 43035.622 | H28: 43035.622 | I28: Created successfully | J28: 1509105323283 | K28: FALSE | M28: TABLE | O28: GA | Q28: last12months | X28: ["visitors"] | Y28: ["Source"] | Z28: ["Yearmonth"] | AA28: [] | AB28: [] | AD28: 100 | AE28: 20 | AF28: [] | AG28: {} | AP28: RawData'!B30:N130
D29: =IFERROR(__xludf.DUMMYFUNCTION("ARRAY_CONSTRAIN(split(CELL(""ADDRESS"",zsupermetrics_1uIP5Fck3SwdBmsjEq8nCC93kef8Z8),""!""),1,1)"),"#NAME?") -> #NAME? | E29: =CELL("ADDRESS",zsupermetrics_1uIP5Fck3SwdBmsjEq8nCC93kef8Z8)&":"&address(row(zsupermetrics_1uIP5Fck3SwdBmsjEq8nCC93kef8Z8)+rows(zsupermetrics_1uIP5Fck3SwdBmsjEq8nCC93kef8Z8)-1,column(zsupermetrics_1uIP5Fck3SwdBmsjEq8nCC93kef8Z8)+COLUMNS(zsupermetrics_1uIP5Fck3SwdBmsjEq8nCC93kef8Z8)-1) -> #NAME? | G29: 43035.622 | H29: 43035.622 | I29: Created successfully | J29: 1509105323283 | K29: FALSE | M29: TABLE | O29: GA | Q29: lastmonth | T29: prev | U29: perc | X29: ["visitors"] | Y29: ["Source"] | Z29: [] | AA29: [] | AB29: [] | AD29: 10000 | AE29: 10 | AF29: ["NO_HEADERS"] | AG29: {} | AP29: Traffic'!B21:D435

Sheet Traffic Dashboard
B1: Supermetrics Tip ➜ | D1: See instructions on the last tab
B2: Website Traffic Dashboard
B3: Purpose
B5: This dashboard will provide you an overview of your key metrics in Google Analytics and will help you get more insight into your best performing traffic sources.
B10: ="Report for "&UPPER( TEXT(TODAY()-DAY(TODAY()),"MMMM YYYY")) -> Report for JULY 2026
I13: Metrics | L13: Change % | M13: 12 month trend
I14: Users | J14: =RawData!AA3 -> 33825 | L14: =RawData!AB3 -> 17.62
I15: Sessions | J15: =RawData!AA4 -> 49694 | L15: =RawData!AB4 -> 20.87
I16: Bounce rate | J16: =RawData!AA5 -> 61.81 | L16: =RawData!AB5 -> 0.22
I17: New sessions % | J17: =RawData!AA6 -> 57.62 | L17: =RawData!AB6 -> -3.81
I18: Pageviews | J18: =RawData!AA7 -> 100358 | L18: =RawData!AB7 -> 23.31
I19: Avg. session length | J19: =RawData!AA8 -> 1.93 | L19: =RawData!AB8 -> 0.17
I20: Transactions | J20: =RawData!AA9 -> 1475 | L20: =RawData!AB9 -> 1.3
I21: Transaction revenue | J21: =RawData!AA10 -> 249040.36 | L21: =RawData!AB10 -> -5.22
I24: Segments | L24: Change % | M24: 12 month trend
I25: Converters | J25: {=iferror(index(RawData!$AA$15:$AA$18,match($I25,RawData!$Z$15:$Z$18,0)),"")} -> 9973 | L25: {=iferror(index(RawData!$AB$15:$AB$18,match($I25,RawData!$Z$15:$Z$18,0)),"")} -> 21.24 | M25: =IFERROR(__xludf.DUMMYFUNCTION("iferror(sparkline(offset(RawData!AE$14:AP$14,match(I25,RawData!AD$15:AD$18,0),0),{""charttype"",""column"";""empty"",""zero"";""ymin"",0;""lowcolor"",""#D19599"";""highcolor"",""#A1D3A8""}),"""")"),"")
I26: Mobile traffic | J26: {=iferror(index(RawData!$AA$15:$AA$18,match($I26,RawData!$Z$15:$Z$18,0)),"")} -> 6322 | L26: {=iferror(index(RawData!$AB$15:$AB$18,match($I26,RawData!$Z$15:$Z$18,0)),"")} -> -4.72 | M26: =IFERROR(__xludf.DUMMYFUNCTION("iferror(sparkline(offset(RawData!AE$14:AP$14,match(I26,RawData!AD$15:AD$18,0),0),{""charttype"",""column"";""empty"",""zero"";""ymin"",0;""lowcolor"",""#D19599"";""highcolor"",""#A1D3A8""}),"""")"),"")
I27: Made a purchase | J27: {=iferror(index(RawData!$AA$15:$AA$18,match($I27,RawData!$Z$15:$Z$18,0)),"")} -> 1405 | L27: {=iferror(index(RawData!$AB$15:$AB$18,match($I27,RawData!$Z$15:$Z$18,0)),"")} -> 2.86 | M27: =IFERROR(__xludf.DUMMYFUNCTION("iferror(sparkline(offset(RawData!AE$14:AP$14,match(I27,RawData!AD$15:AD$18,0),0),{""charttype"",""column"";""empty"",""zero"";""ymin"",0;""lowcolor"",""#D19599"";""highcolor"",""#A1D3A8""}),"""")"),"")
I28: Tablet traffic | J28: {=iferror(index(RawData!$AA$15:$AA$18,match($I28,RawData!$Z$15:$Z$18,0)),"")} -> 485 | L28: {=iferror(index(RawData!$AB$15:$AB$18,match($I28,RawData!$Z$15:$Z$18,0)),"")} -> -0.21 | M28: =IFERROR(__xludf.DUMMYFUNCTION("iferror(sparkline(offset(RawData!AE$14:AP$14,match(I28,RawData!AD$15:AD$18,0),0),{""charttype"",""column"";""empty"",""zero"";""ymin"",0;""lowcolor"",""#D19599"";""highcolor"",""#A1D3A8""}),"""")"),"")
B32: Top 20 Traffic Sources
B35: Ranking | C35: Source | E35: Users | F35: Change % | H35: 12 month trend | L35: Top landing page | M35: New users % | N35: Bounce rate %
B36: 1 | C36: google | E36: 12635 | F36: 26.39 | H36: =IFERROR(__xludf.DUMMYFUNCTION("iferror(sparkline(offset(RawData!C$31:N$31,match(C36,RawData!B$31:B$57,0)-1,0),{""charttype"",""column"";""empty"",""zero"";""ymin"",0;""lowcolor"",""#D19599"";""highcolor"",""#A1D3A8""}),"""")"),"") | L36: {=iferror(index(RawData!R:R,match(C36,RawData!Q:Q,0)),"")} -> /blog/article2/ | M36: {=iferror(index(RawData!X:X,match(C36,RawData!U:U,0)),"")} -> 47.36 | N36: {=iferror(index(RawData!W:W,match(C36,RawData!U:U,0)),"")} -> 52.67
B37: 2 | C37: (direct) | E37: 10284 | F37: 40.74 | H37: =IFERROR(__xludf.DUMMYFUNCTION("iferror(sparkline(offset(RawData!C$31:N$31,match(C37,RawData!B$31:B$57,0)-1,0),{""charttype"",""column"";""empty"",""zero"";""ymin"",0;""lowcolor"",""#D19599"";""highcolor"",""#A1D3A8""}),"""")"),"") | L37: {=iferror(index(RawData!R:R,match(C37,RawData!Q:Q,0)),"")} -> /blog/article2/ | M37: {=iferror(index(RawData!X:X,match(C37,RawData!U:U,0)),"")} -> 67.21 | N37: {=iferror(index(RawData!W:W,match(C37,RawData!U:U,0)),"")} -> 59.35
B38: 3 | C38: facebook | E38: 3748 | F38: -33.12 | H38: =IFERROR(__xludf.DUMMYFUNCTION("iferror(sparkline(offset(RawData!C$31:N$31,match(C38,RawData!B$31:B$57,0)-1,0),{""charttype"",""column"";""empty"",""zero"";""ymin"",0;""lowcolor"",""#D19599"";""highcolor"",""#A1D3A8""}),"""")"),"") | L38: {=iferror(index(RawData!R:R,match(C38,RawData!Q:Q,0)),"")} -> /blog/article1/ | M38: {=iferror(index(RawData!X:X,match(C38,RawData!U:U,0)),"")} -> 77.55 | N38: {=iferror(index(RawData!W:W,match(C38,RawData!U:U,0)),"")} -> 90.17
B39: 4 | C39: adwords | E39: 1839 | F39: -39.37 | H39: =IFERROR(__xludf.DUMMYFUNCTION("iferror(sparkline(offset(RawData!C$31:N$31,match(C39,RawData!B$31:B$57,0)-1,0),{""charttype"",""column"";""empty"",""zero"";""ymin"",0;""lowcolor"",""#D19599"";""highcolor"",""#A1D3A8""}),"""")"),"") | L39: {=iferror(index(RawData!R:R,match(C39,RawData!Q:Q,0)),"")} -> /blog/article4/ | M39: {=iferror(index(RawData!X:X,match(C39,RawData!U:U,0)),"")} -> 63.19 | N39: {=iferror(index(RawData!W:W,match(C39,RawData!U:U,0)),"")} -> 70
B40: 5 | C40: adwords | E40: 1546 | F40: 77200 | H40: =IFERROR(__xludf.DUMMYFUNCTION("iferror(sparkline(offset(RawData!C$31:N$31,match(C40,RawData!B$31:B$57,0)-1,0),{""charttype"",""column"";""empty"",""zero"";""ymin"",0;""lowcolor"",""#D19599"";""highcolor"",""#A1D3A8""}),"""")"),"") | L40: {=iferror(index(RawData!R:R,match(C40,RawData!Q:Q,0)),"")} -> /blog/article4/ | M40: {=iferror(index(RawData!X:X,match(C40,RawData!U:U,0)),"")} -> 63.19 | N40: {=iferror(index(RawData!W:W,match(C40,RawData!U:U,0)),"")} -> 70
B41: 6 | C41: adwords | E41: 1276 | H41: =IFERROR(__xludf.DUMMYFUNCTION("iferror(sparkline(offset(RawData!C$31:N$31,match(C41,RawData!B$31:B$57,0)-1,0),{""charttype"",""column"";""empty"",""zero"";""ymin"",0;""lowcolor"",""#D19599"";""highcolor"",""#A1D3A8""}),"""")"),"") | L41: {=iferror(index(RawData!R:R,match(C41,RawData!Q:Q,0)),"")} -> /blog/article4/ | M41: {=iferror(index(RawData!X:X,match(C41,RawData!U:U,0)),"")} -> 63.19 | N41: {=iferror(index(RawData!W:W,match(C41,RawData!U:U,0)),"")} -> 70
B42: 7 | C42: facebook.com | E42: 488 | F42: 29.79 | H42: =IFERROR(__xludf.DUMMYFUNCTION("iferror(sparkline(offset(RawData!C$31:N$31,match(C42,RawData!B$31:B$57,0)-1,0),{""charttype"",""column"";""empty"",""zero"";""ymin"",0;""lowcolor"",""#D19599"";""highcolor"",""#A1D3A8""}),"""")"),"") | L42: {=iferror(index(RawData!R:R,match(C42,RawData!Q:Q,0)),"")} | M42: {=iferror(index(RawData!X:X,match(C42,RawData!U:U,0)),"")} -> 59.88 | N42: {=iferror(index(RawData!W:W,match(C42,RawData!U:U,0)),"")} -> 87.99
B43: 8 | C43: linkedin.com | E43: 428 | F43: 69.17 | H43: =IFERROR(__xludf.DUMMYFUNCTION("iferror(sparkline(offset(RawData!C$31:N$31,match(C43,RawData!B$31:B$57,0)-1,0),{""charttype"",""column"";""empty"",""zero"";""ymin"",0;""lowcolor"",""#D19599"";""highcolor"",""#A1D3A8""}),"""")"),"") | L43: {=iferror(index(RawData!R:R,match(C43,RawData!Q:Q,0)),"")} | M43: {=iferror(index(RawData!X:X,match(C43,RawData!U:U,0)),"")} -> 52.59 | N43: {=iferror(index(RawData!W:W,match(C43,RawData!U:U,0)),"")} -> 78.18
B44: 9 | C44: twitter | E44: 359 | F44: -43.46 | H44: =IFERROR(__xludf.DUMMYFUNCTION("iferror(sparkline(offset(RawData!C$31:N$31,match(C44,RawData!B$31:B$57,0)-1,0),{""charttype"",""column"";""empty"",""zero"";""ymin"",0;""lowcolor"",""#D19599"";""highcolor"",""#A1D3A8""}),"""")"),"") | L44: {=iferror(index(RawData!R:R,match(C44,RawData!Q:Q,0)),"")} -> /blog/article4/ | M44: {=iferror(index(RawData!X:X,match(C44,RawData!U:U,0)),"")} -> 69.98 | N44: {=iferror(index(RawData!W:W,match(C44,RawData!U:U,0)),"")} -> 86.18
B45: 10 | C45: t.co | E45: 356 | F45: 102.27 | H45: =IFERROR(__xludf.DUMMYFUNCTION("iferror(sparkline(offset(RawData!C$31:N$31,match(C45,RawData!B$31:B$57,0)-1,0),{""charttype"",""column"";""empty"",""zero"";""ymin"",0;""lowcolor"",""#D19599"";""highcolor"",""#A1D3A8""}),"""")"),"") | L45: {=iferror(index(RawData!R:R,match(C45,RawData!Q:Q,0)),"")} -> /blog/article3/ | M45: {=iferror(index(RawData!X:X,match(C45,RawData!U:U,0)),"")} -> 64.85 | N45: {=iferror(index(RawData!W:W,match(C45,RawData!U:U,0)),"")} -> 73.24
B46: 11 | C46: bing | E46: 333 | F46: 31.62 | H46: =IFERROR(__xludf.DUMMYFUNCTION("iferror(sparkline(offset(RawData!C$31:N$31,match(C46,RawData!B$31:B$57,0)-1,0),{""charttype"",""column"";""empty"",""zero"";""ymin"",0;""lowcolor"",""#D19599"";""highcolor"",""#A1D3A8""}),"""")"),"") | L46: {=iferror(index(RawData!R:R,match(C46,RawData!Q:Q,0)),"")} | M46: {=iferror(index(RawData!X:X,match(C46,RawData!U:U,0)),"")} -> 90.25 | N46: {=iferror(index(RawData!W:W,match(C46,RawData!U:U,0)),"")} -> 78.27
B47: 12 | C47: bing | E47: 229 | F47: -1.29 | H47: =IFERROR(__xludf.DUMMYFUNCTION("iferror(sparkline(offset(RawData!C$31:N$31,match(C47,RawData!B$31:B$57,0)-1,0),{""charttype"",""column"";""empty"",""zero"";""ymin"",0;""lowcolor"",""#D19599"";""highcolor"",""#A1D3A8""}),"""")"),"") | L47: {=iferror(index(RawData!R:R,match(C47,RawData!Q:Q,0)),"")} | M47: {=iferror(index(RawData!X:X,match(C47,RawData!U:U,0)),"")} -> 90.25 | N47: {=iferror(index(RawData!W:W,match(C47,RawData!U:U,0)),"")} -> 78.27
B48: 13 | C48: t.co | E48: 227 | F48: 22.7 | H48: =IFERROR(__xludf.DUMMYFUNCTION("iferror(sparkline(offset(RawData!C$31:N$31,match(C48,RawData!B$31:B$57,0)-1,0),{""charttype"",""column"";""empty"",""zero"";""ymin"",0;""lowcolor"",""#D19599"";""highcolor"",""#A1D3A8""}),"""")"),"") | L48: {=iferror(index(RawData!R:R,match(C48,RawData!Q:Q,0)),"")} -> /blog/article3/ | M48: {=iferror(index(RawData!X:X,match(C48,RawData!U:U,0)),"")} -> 64.85 | N48: {=iferror(index(RawData!W:W,match(C48,RawData!U:U,0)),"")} -> 73.24
B49: 14 | C49: quora.com | E49: 227 | F49: 8.61 | H49: =IFERROR(__xludf.DUMMYFUNCTION("iferror(sparkline(offset(RawData!C$31:N$31,match(C49,RawData!B$31:B$57,0)-1,0),{""charttype"",""column"";""empty"",""zero"";""ymin"",0;""lowcolor"",""#D19599"";""highcolor"",""#A1D3A8""}),"""")"),"") | L49: {=iferror(index(RawData!R:R,match(C49,RawData!Q:Q,0)),"")} | M49: {=iferror(index(RawData!X:X,match(C49,RawData!U:U,0)),"")} -> 71.27 | N49: {=iferror(index(RawData!W:W,match(C49,RawData!U:U,0)),"")} -> 74.63
B50: 15 | C50: twitter.com | E50: 225 | F50: -61.21 | H50: =IFERROR(__xludf.DUMMYFUNCTION("iferror(sparkline(offset(RawData!C$31:N$31,match(C50,RawData!B$31:B$57,0)-1,0),{""charttype"",""column"";""empty"",""zero"";""ymin"",0;""lowcolor"",""#D19599"";""highcolor"",""#A1D3A8""}),"""")"),"") | L50: {=iferror(index(RawData!R:R,match(C50,RawData!Q:Q,0)),"")} | M50: {=iferror(index(RawData!X:X,match(C50,RawData!U:U,0)),"")} -> 43.88 | N50: {=iferror(index(RawData!W:W,match(C50,RawData!U:U,0)),"")} -> 73.81
B51: 16 | C51: linkedin.com | E51: 159 | F51: 318.42 | H51: =IFERROR(__xludf.DUMMYFUNCTION("iferror(sparkline(offset(RawData!C$31:N$31,match(C51,RawData!B$31:B$57,0)-1,0),{""charttype"",""column"";""empty"",""zero"";""ymin"",0;""lowcolor"",""#D19599"";""highcolor"",""#A1D3A8""}),"""")"),"") | L51: {=iferror(index(RawData!R:R,match(C51,RawData!Q:Q,0)),"")} | M51: {=iferror(index(RawData!X:X,match(C51,RawData!U:U,0)),"")} -> 52.59 | N51: {=iferror(index(RawData!W:W,match(C51,RawData!U:U,0)),"")} -> 78.18
B52: 17 | C52: linkedin.com | E52: 131 | F52: 45.56 | H52: =IFERROR(__xludf.DUMMYFUNCTION("iferror(sparkline(offset(RawData!C$31:N$31,match(C52,RawData!B$31:B$57,0)-1,0),{""charttype"",""column"";""empty"",""zero"";""ymin"",0;""lowcolor"",""#D19599"";""highcolor"",""#A1D3A8""}),"""")"),"") | L52: {=iferror(index(RawData!R:R,match(C52,RawData!Q:Q,0)),"")} | M52: {=iferror(index(RawData!X:X,match(C52,RawData!U:U,0)),"")} -> 52.59 | N52: {=iferror(index(RawData!W:W,match(C52,RawData!U:U,0)),"")} -> 78.18
B53: 18 | C53: linkedin.com | E53: 117 | F53: 134 | H53: =IFERROR(__xludf.DUMMYFUNCTION("iferror(sparkline(offset(RawData!C$31:N$31,match(C53,RawData!B$31:B$57,0)-1,0),{""charttype"",""column"";""empty"",""zero"";""ymin"",0;""lowcolor"",""#D19599"";""highcolor"",""#A1D3A8""}),"""")"),"") | L53: {=iferror(index(RawData!R:R,match(C53,RawData!Q:Q,0)),"")} | M53: {=iferror(index(RawData!X:X,match(C53,RawData!U:U,0)),"")} -> 52.59 | N53: {=iferror(index(RawData!W:W,match(C53,RawData!U:U,0)),"")} -> 78.18
B54: 19 | C54: linkedin.com | E54: 99 | F54: -25.56 | H54: =IFERROR(__xludf.DUMMYFUNCTION("iferror(sparkline(offset(RawData!C$31:N$31,match(C54,RawData!B$31:B$57,0)-1,0),{""charttype"",""column"";""empty"",""zero"";""ymin"",0;""lowcolor"",""#D19599"";""highcolor"",""#A1D3A8""}),"""")"),"") | L54: {=iferror(index(RawData!R:R,match(C54,RawData!Q:Q,0)),"")} | M54: {=iferror(index(RawData!X:X,match(C54,RawData!U:U,0)),"")} -> 52.59 | N54: {=iferror(index(RawData!W:W,match(C54,RawData!U:U,0)),"")} -> 78.18
...

Sheet RawData
B1: Cells in this color are raw data pulled via Supermetrics | G1: Cells in this color are calculations
Q2: Top 20 Traffic Sources - Top landing page | U2: Top 20 Traffic Sources - New Users % and Bounce Rate % | Z2: Metrics | AD2: Metrics - Last 12 Months - For the Bar Charts
B3: User by Medium and Month Chart - Raw Data for the Calculated Metrics Chart below | Q3: Source | R3: Landing page path | S3: Entrances | U3: Source | V3: Users | W3: Bounce rate | X3: New sessions % | Z3: Users | AA3: 33825 | AB3: 17.62 | AE3: 2016|10 | AF3: 2016|11 | AG3: 2016|12 | AH3: 2017|01 | AI3: 2017|02 | AJ3: 2017|03 | AK3: 2017|04 | AL3: 2017|05 | AM3: 2017|06 | AN3: 2017|07 | AO3: 2017|08 | AP3: 2017|09
B4: Medium | C4: 2016|10 | D4: 2016|11 | E4: 2016|12 | F4: 2017|01 | G4: 2017|02 | H4: 2017|03 | I4: 2017|04 | J4: 2017|05 | K4: 2017|06 | L4: 2017|07 | M4: 2017|08 | N4: 2017|09 | Q4: google | R4: /blog/article2/ | S4: 5704 | U4: google | V4: 12635 | W4: 52.67 | X4: 47.36 | Z4: Sessions | AA4: 49694 | AB4: 20.87 | AD4: Users | AE4: 17407 | AF4: 17389 | AG4: 17184 | AH4: 20096 | AI4: 19905 | AJ4: 21722 | AK4: 19165 | AL4: 21011 | AM4: 24230 | AN4: 28250 | AO4: 29933 | AP4: 33825
B5: organic | C5: 5308 | D5: 4740 | E5: 3870 | F5: 6833 | G5: 7186 | H5: 8668 | I5: 7633 | J5: 9009 | K5: 9201 | L5: 9232 | M5: 10139 | N5: 12278 | O5: =sum(C5:N5)/sum(C$5:N$5)>0.01 -> TRUE | Q5: (direct) | R5: /blog/article2/ | S5: 2861 | U5: (direct) | V5: 10284 | W5: 59.35 | X5: 67.21 | Z5: Bounce rate | AA5: 61.81 | AB5: 0.22 | AD5: Sessions | AE5: 25442 | AF5: 26859 | AG5: 24703 | AH5: 30527 | AI5: 30214 | AJ5: 33796 | AK5: 29160 | AL5: 32443 | AM5: 36129 | AN5: 41049 | AO5: 43017 | AP5: 49694
B6: (none) | C6: 5405 | D6: 5518 | E6: 5319 | F6: 6473 | G6: 5771 | H6: 7234 | I6: 6360 | J6: 7287 | K6: 7761 | L6: 7510 | M6: 7629 | N6: 10284 | O6: =sum(C6:N6)/sum(C$5:N$5)>0.01 -> TRUE | Q6: (direct) | R6: /blog/article1/ | S6: 2208 | U6: facebook | V6: 3748 | W6: 90.17 | X6: 77.55 | Z6: New sessions % | AA6: 57.62 | AB6: -3.81 | AD6: Bounce rate | AE6: 57.17 | AF6: 55.99 | AG6: 55.17 | AH6: 58.33 | AI6: 58.99 | AJ6: 56.9 | AK6: 56.42 | AL6: 55.69 | AM6: 57.79 | AN6: 61.89 | AO6: 61.67 | AP6: 61.81
B7: cpc | C7: 4366 | D7: 4779 | E7: 4739 | F7: 4469 | G7: 4687 | H7: 2828 | I7: 2272 | J7: 3104 | K7: 4672 | L7: 9606 | M7: 10200 | N7: 6819 | O7: =sum(C7:N7)/sum(C$5:N$5)>0.01 -> TRUE | Q7: facebook | R7: /blog/article1/ | S7: 1543 | U7: adwords | V7: 1839 | W7: 70 | X7: 63.19 | Z7: Pageviews | AA7: 100358 | AB7: 23.31 | AD7: New sessions % | AE7: 59.94 | AF7: 56.26 | AG7: 61.26 | AH7: 58.23 | AI7: 56.93 | AJ7: 55.85 | AK7: 54.38 | AL7: 55.02 | AM7: 57.65 | AN7: 60.15 | AO7: 59.67 | AP7: 57.62
B8: referral | C8: 3361 | D8: 3671 | E8: 4369 | F8: 4004 | G8: 3460 | H8: 4505 | I8: 4022 | J8: 2621 | K8: 3706 | L8: 2759 | M8: 2547 | N8: 5810 | O8: =sum(C8:N8)/sum(C$5:N$5)>0.01 -> TRUE | Q8: facebook | R8: /blog/article1/ | S8: 1519 | U8: adwords | V8: 1546 | W8: 59.1 | X8: 46.85 | Z8: Avg. session length (min) | AA8: 1.93 | AB8: 0.17 | AD8: Pageviews | AE8: 54646 | AF8: 58092 | AG8: 51001 | AH8: 64492 | AI8: 62092 | AJ8: 72613 | AK8: 61149 | AL8: 69394 | AM8: 77123 | AN8: 81190 | AO8: 84981 | AP8: 100358
B9: social | C9: 122 | D9: 147 | E9: 94 | F9: 105 | G9: 87 | H9: 101 | I9: 228 | J9: 322 | K9: 292 | L9: 721 | M9: 1049 | N9: 753 | O9: =sum(C9:N9)/sum(C$5:N$5)>0.01 -> TRUE | Q9: google | R9: /blog/article2/ | S9: 1461 | U9: adwords | V9: 1276 | W9: 60.13 | X9: 62.22 | Z9: Transactions | AA9: 1475 | AB9: 1.3 | AD9: Avg. session length (min) | AE9: 2.01 | AF9: 2.16 | AG9: 1.79 | AH9: 2.1 | AI9: 1.98 | AJ9: 2.1 | AK9: 2.15 | AL9: 2.33 | AM9: 2.21 | AN9: 1.9 | AO9: 1.93 | AP9: 1.93
B10: paid | F10: 42 | G10: 537 | H10: 744 | I10: 460 | J10: 311 | K10: 132 | L10: 113 | M10: 76 | N10: 52 | O10: =sum(C10:N10)/sum(C$5:N$5)>0.01 -> TRUE | Q10: google | R10: /blog/article3/ | S10: 1289 | U10: facebook.com | V10: 488 | W10: 87.99 | X10: 59.88 | Z10: Transaction revenue | AA10: 249040.36 | AB10: -5.22 | AD10: Transactions | AE10: 831 | AF10: 916 | AG10: 852 | AH10: 1045 | AI10: 980 | AJ10: 1139 | AK10: 1180 | AL10: 1332 | AM10: 1335 | AN10: 1448 | AO10: 1518 | AP10: 1475
B11: email | C11: 93 | D11: 89 | E11: 22 | F11: 37 | G11: 9 | H11: 53 | I11: 15 | J11: 40 | K11: 225 | L11: 16 | M11: 39 | N11: 87 | O11: =sum(C11:N11)/sum(C$5:N$5)>0.01 -> FALSE | Q11: google | R11: /blog/article6/ | S11: 1137 | U11: linkedin.com | V11: 428 | W11: 78.18 | X11: 52.59 | AD11: Transaction revenue | AE11: 145956.01 | AF11: 163121.47 | AG11: 156557.21 | AH11: 195606.49 | AI11: 187066.02 | AJ11: 211149.5 | AK11: 206230.9 | AL11: 239271.85 | AM11: 226886.26 | AN11: 247631.35 | AO11: 273317.81 | AP11: 249040.36
B12: (not set) | C12: 2 | D12: 2 | E12: 1 | F12: 1 | K12: 9 | L12: 9 | M12: 44 | N12: 17 | O12: =sum(C12:N12)/sum(C$5:N$5)>0.01 -> FALSE | Q12: (direct) | R12: /blog/article7/ | S12: 947 | U12: twitter | V12: 359 | W12: 86.18 | X12: 69.98
B13: facebook | M13: 35 | N13: 2 | O13: =sum(C13:N13)/sum(C$5:N$5)>0.01 -> FALSE | Q13: (direct) | R13: /blog/article8/ | S13: 923 | U13: t.co | V13: 356 | W13: 73.24 | X13: 64.85 | Z13: Segments | AD13: Segments - Last 12 Months - For the Bar Charts
B14: feed | C14: 1 | D14: 5 | E14: 2 | F14: 6 | H14: 1 | O14: =sum(C14:N14)/sum(C$5:N$5)>0.01 -> FALSE | Q14: google | R14: /blog/article9/ | S14: 831 | U14: bing | V14: 333 | W14: 78.27 | X14: 90.25 | Z14: Segment | AA14: Users | AB14: Change % | AD14: Segment | AE14: 2016|10 | AF14: 2016|11 | AG14: 2016|12 | AH14: 2017|01 | AI14: 2017|02 | AJ14: 2017|03 | AK14: 2017|04 | AL14: 2017|05 | AM14: 2017|06 | AN14: 2017|07 | AO14: 2017|08 | AP14: 2017|09
Q15: (direct) | R15: /blog/article3/ | S15: 654 | U15: bing | V15: 229 | W15: 85.37 | X15: 35.23 | Z15: Converters | AA15: 9973 | AB15: 21.24 | AD15: Converters | AE15: 6034 | AF15: 6297 | AG15: 5482 | AH15: 7494 | AI15: 7365 | AJ15: 8548 | AK15: 7662 | AL15: 8823 | AM15: 9218 | AN15: 9561 | AO15: 10039 | AP15: 11205
B16: User by Medium and Month Chart | Q16: t.co | R16: /blog/article3/ | S16: 642 | U16: bing | V16: 227 | W16: 92.89 | X16: 86.17 | Z16: Mobile Traffic | AA16: 6322 | AB16: -4.72 | AD16: Mobile Traffic | AE16: 4440 | AF16: 4016 | AG16: 5325 | AH16: 3650 | AI16: 4448 | AJ16: 2855 | AK16: 2224 | AL16: 1997 | AM16: 3549 | AN16: 6370 | AO16: 6859 | AP16: 6322
B17: =B4 -> Medium | C17: =C4 -> 2016|10 | D17: =D4 -> 2016|11 | E17: =E4 -> 2016|12 | F17: =F4 -> 2017|01 | G17: =G4 -> 2017|02 | H17: =H4 -> 2017|03 | I17: =I4 -> 2017|04 | ... N17: =N4 -> 2017|09 | Q17: google | R17: /blog/article4/ | S17: 525 | U17: quora.com | V17: 227 | W17: 74.63 | X17: 71.27 | Z17: Made a Purchase | AA17: 1405 | AB17: 2.86 | AD17: Made a Purchase | AE17: 1012 | AF17: 1219 | AG17: 1147 | AH17: 1404 | AI17: 1411 | AJ17: 1595 | AK17: 1618 | AL17: 1833 | AM17: 1836 | AN17: 1905 | AO17: 1953 | AP17: 1861
B18: =if($O5,B5,"") -> organic | C18: =if($O5,C5,"") -> 5308 | D18: =if($O5,D5,"") -> 4740 | E18: =if($O5,E5,"") -> 3870 | F18: =if($O5,F5,"") -> 6833 | G18: =if($O5,G5,"") -> 7186 | H18: =if($O5,H5,"") -> 8668 | I18: =if($O5,I5,"") -> 7633 | ... N18: =if($O5,N5,"") -> 12278 | Q18: google | R18: /blog/article4/ | S18: 507 | U18: twitter.com | V18: 225 | W18: 73.81 | X18: 43.88 | Z18: Tablet Traffic | AA18: 485 | AB18: -0.21 | AD18: Tablet Traffic | AE18: 396 | AF18: 232 | AG18: 243 | AH18: 244 | AI18: 192 | AJ18: 285 | AK18: 220 | AL18: 230 | AM18: 394 | AN18: 435 | AO18: 509 | AP18: 485
B19: =if($O6,B6,"") -> (none) | C19: =if($O6,C6,"") -> 5405 | D19: =if($O6,D6,"") -> 5518 | E19: =if($O6,E6,"") -> 5319 | F19: =if($O6,F6,"") -> 6473 | G19: =if($O6,G6,"") -> 5771 | H19: =if($O6,H6,"") -> 7234 | I19: =if($O6,I6,"") -> 6360 | ... N19: =if($O6,N6,"") -> 10284 | Q19: google | R19: /blog/article4/ | S19: 471 | U19: plus.google.com | V19: 159 | W19: 73.91 | X19: 50.43
B20: =if($O7,B7,"") -> cpc | C20: =if($O7,C7,"") -> 4366 | D20: =if($O7,D7,"") -> 4779 | E20: =if($O7,E7,"") -> 4739 | F20: =if($O7,F7,"") -> 4469 | G20: =if($O7,G7,"") -> 4687 | H20: =if($O7,H7,"") -> 2828 | I20: =if($O7,I7,"") -> 2272 | ... N20: =if($O7,N7,"") -> 6819 | Q20: google | R20: /blog/article4/ | S20: 460 | U20: moz.com | V20: 131 | W20: 62.03 | X20: 78.48
B21: =if($O8,B8,"") -> referral | C21: =if($O8,C8,"") -> 3361 | D21: =if($O8,D8,"") -> 3671 | E21: =if($O8,E8,"") -> 4369 | F21: =if($O8,F8,"") -> 4004 | G21: =if($O8,G8,"") -> 3460 | H21: =if($O8,H8,"") -> 4505 | I21: =if($O8,I8,"") -> 4022 | ... N21: =if($O8,N8,"") -> 5810 | Q21: adwords | R21: /blog/article4/ | S21: 448 | U21: moz.com | V21: 117 | W21: 65.02 | X21: 32.02
B22: =if($O9,B9,"") -> social | C22: =if($O9,C9,"") -> 122 | D22: =if($O9,D9,"") -> 147 | E22: =if($O9,E9,"") -> 94 | F22: =if($O9,F9,"") -> 105 | G22: =if($O9,G9,"") -> 87 | H22: =if($O9,H9,"") -> 101 | I22: =if($O9,I9,"") -> 228 | ... N22: =if($O9,N9,"") -> 753 | Q22: (direct) | R22: /blog/article4/ | S22: 435 | U22: moz.com | V22: 99 | W22: 93.52 | X22: 81.48
B23: =if($O10,B10,"") -> paid | C23: =if($O10,C10,"") | D23: =if($O10,D10,"") | E23: =if($O10,E10,"") | F23: =if($O10,F10,"") -> 42 | G23: =if($O10,G10,"") -> 537 | H23: =if($O10,H10,"") -> 744 | I23: =if($O10,I10,"") -> 460 | ... N23: =if($O10,N10,"") -> 52 | Q23: google | R23: /blog/article4/ | S23: 434 | U23: moz.com | V23: 91 | W23: 63.19 | X23: 7.64
B24: =if($O11,B11,"") | C24: =if($O11,C11,"") | D24: =if($O11,D11,"") | E24: =if($O11,E11,"") | F24: =if($O11,F11,"") | G24: =if($O11,G11,"") | H24: =if($O11,H11,"") | I24: =if($O11,I11,"") | ... N24: =if($O11,N11,"") | Q24: google | R24: /blog/article4/ | S24: 426 | U24: moz.com | V24: 86 | W24: 82.42 | X24: 87.91
B25: =if($O12,B12,"") | C25: =if($O12,C12,"") | D25: =if($O12,D12,"") | E25: =if($O12,E12,"") | F25: =if($O12,F12,"") | G25: =if($O12,G12,"") | H25: =if($O12,H12,"") | I25: =if($O12,I12,"") | ... N25: =if($O12,N12,"") | Q25: twitter | R25: /blog/article4/ | S25: 417 | U25: moz.com | V25: 82 | W25: 29.9 | X25: 69.07
B26: =if($O13,B13,"") | C26: =if($O13,C13,"") | D26: =if($O13,D13,"") | E26: =if($O13,E13,"") | F26: =if($O13,F13,"") | G26: =if($O13,G13,"") | H26: =if($O13,H13,"") | I26: =if($O13,I13,"") | ... N26: =if($O13,N13,"") | Q26: google | R26: /blog/article4/ | S26: 415 | U26: moz.com | V26: 77 | W26: 61.29 | X26: 69.89
B27: =if($O14,B14,"") | C27: =if($O14,C14,"") | D27: =if($O14,D14,"") | E27: =if($O14,E14,"") | F27: =if($O14,F14,"") | G27: =if($O14,G14,"") | H27: =if($O14,H14,"") | I27: =if($O14,I14,"") | ... N27: =if($O14,N14,"") | Q27: google | R27: /blog/article4/ | S27: 412 | U27: youtube.com | V27: 74 | W27: 60.22 | X27: 49.46
Q28: (direct) | R28: /blog/article4/ | S28: 395 | U28: youtube.com | V28: 62 | W28: 72 | X28: 16
B29: Top 20 Traffic Sources - Last 12 Months - For the Bar Charts | Q29: (direct) | R29: /blog/article4/ | S29: 353 | U29: youtube.com | V29: 61 | W29: 69.86 | X29: 26.03
B30: Source | C30: 2016|10 | D30: 2016|11 | E30: 2016|12 | F30: 2017|01 | G30: 2017|02 | H30: 2017|03 | I30: 2017|04 | J30: 2017|05 | K30: 2017|06 | L30: 2017|07 | M30: 2017|08 | N30: 2017|09 | Q30: google | R30: /blog/article4/ | S30: 349 | U30: youtube.com | V30: 57 | W30: 55.22 | X30: 76.12
B31: google | C31: 9468 | D31: 9187 | E31: 8270 | F31: 10773 | G31: 11389 | H31: 10727 | I31: 9162 | J31: 9509 | K31: 9356 | L31: 9368 | M31: 10412 | N31: 12635 | Q31: (direct) | R31: /blog/article4/ | S31: 342 | U31: youtube.com | V31: 50 | W31: 36.05 | X31: 15.12
B32: (direct) | C32: 5405 | D32: 5518 | E32: 5319 | F32: 6473 | G32: 5771 | H32: 7234 | I32: 6360 | J32: 7287 | K32: 7761 | L32: 7510 | M32: 7629 | N32: 10284 | Q32: (direct) | R32: /blog/article4/ | S32: 330 | U32: youtube.com | V32: 49 | W32: 80.95 | X32: 60.32
B33: facebook | F33: 42 | G33: 537 | H33: 744 | I33: 313 | J33: 645 | K33: 824 | L33: 5985 | M33: 5788 | N33: 3748 | Q33: google | R33: /blog/article4/ | S33: 288 | U33: medium.com | V33: 48 | W33: 69.64 | X33: 37.5
B34: adwords | J34: 1408 | K34: 2936 | L34: 2848 | M34: 3189 | N34: 1839
B35: adwords | C35: 1501 | D35: 1770 | E35: 1494 | F35: 1943 | G35: 1947 | H35: 2439 | I35: 2109 | J35: 611 | K35: 233 | L35: 163 | M35: 97 | N35: 38
B36: adwords | M36: 2 | N36: 1546
B37: twitter.com | N37: 1276
B38: twitter.com | K38: 766 | L38: 473 | M38: 133 | N38: 99
B39: twitter.com | C39: 120 | D39: 100 | E39: 694 | F39: 46 | G39: 54 | H39: 43 | I39: 84 | J39: 134 | K39: 144 | L39: 406 | M39: 594 | N39: 225
B40: reddit.com | C40: 14 | D40: 162 | E40: 685 | F40: 18 | G40: 51 | H40: 14 | I40: 55 | J40: 61 | K40: 121 | L40: 44 | M40: 164 | N40: 43
...

Sheet Instructions
B2: Instructions
B4: This sheet helps pull in data directly from Google Analytics to create a report on the performance of paid traffic. It can be used with the Supermetrics Google Sheets add-on to pull in PPC, SEO, social media and web analytics data into Google Sheets for reporting, monitoring, and analysis.
B5: Supermetrics Tip ➜
B7: We recommend you use a Google Analytics account which has paid traffic for at least the last 13 months. Otherwise, you will be missing data for year-over-year comparison and 12-month trend lines.
B11: Getting Started
B13: Option 1 If you see a welcome sidebar about Supermetrics
B14: > Click on the button in the welcome sidebar to install the Supermetrics Google Sheets add-on
B15: > Follow instructions to connect to your Google Analytics account and apply the template
B17: Option 2 If you do not see a welcome sidebar
B18: > Copy the url of this sheet from the address bar
B19: > Install the Supermetrics add-on with the link below (skip this if you've installed the add-on)
B20: > Launch the Supermetrics sidebar (Add-ons menu -> Supermetrics -> Launch sidebar)
... B23: > Authorize Supermetrics to access your Google Analytics accounts, select the view you want to report on, and click on Insert Template
B24: =HYPERLINK("https://chrome.google.com/webstore/detail/supermetrics/bnkdidgbiidpnohlnhmkehlimlnfhgce","Install Supermetrics for Google Sheets") -> Install Supermetrics for Google Sheets
B26: Option 3 If you wish to use this template without the Supermetrics add-on
B27: > Manually copy / paste data from Google Analytics into the blue cells in the "RawData" tab.
